Workbook

Sheet RESUMEN
B2: IMPORTACIONES RUBI HA ABRIL
B4: Customer Name | C4: Division | D4: Promotion No | E4: Promotion Name | F4: From | G4: To | H4: SPMS | I4: Cálculo LG | J4: Diferencia | K4: Retorno/Exceso
B5: IMPORTACIONES RUBI S.A. | C5: Cooking | D5: PR-NTSO-20240405-0031 | E5: 2024 - RUBI - Cooking - 20240410 AL 20240430 | F5: 20240410 | G5: 20240430 | H5: =SUMIF('CALCULATE (2)'!$D:$D,RESUMEN!$D5,'CALCULATE (2)'!$BA:$BA) -> 5796.56 | I5: =SUMIF('CALCULATE (2)'!$D:$D,RESUMEN!$D5,'CALCULATE (2)'!$V:$V) -> 5796.56 | J5: =+I5-H5 -> 0 | K5: =+IF(J5<=0,"Retorno","Exceso") -> Retorno
B6: IMPORTACIONES RUBI S.A. | C6: Cooking | D6: PR-NTSO-20240415-0011 | E6: 2024 - RUBI - Cooking - 20240420 AL 20240430 | F6: 20240420 | G6: 20240430 | H6: =SUMIF('CALCULATE (2)'!$D:$D,RESUMEN!$D6,'CALCULATE (2)'!$BA:$BA) -> 1601.67 | I6: =SUMIF('CALCULATE (2)'!$D:$D,RESUMEN!$D6,'CALCULATE (2)'!$V:$V) -> 0 | J6: =+I6-H6 -> -1601.67 | K6: =+IF(J6<=0,"Retorno","Exceso") -> Retorno
B7: IMPORTACIONES RUBI S.A. | C7: Cooking | D7: PR-NTSO-20240416-0005 | E7: 2024 - RUBI - Cooking - 20240422 AL 20240430 | F7: 20240422 | G7: 20240430 | H7: =SUMIF('CALCULATE (2)'!$D:$D,RESUMEN!$D7,'CALCULATE (2)'!$BA:$BA) -> 8313.9 | I7: =SUMIF('CALCULATE (2)'!$D:$D,RESUMEN!$D7,'CALCULATE (2)'!$V:$V) -> 7245.7 | J7: =+I7-H7 -> -1068.2 | K7: =+IF(J7<=0,"Retorno","Exceso") -> Retorno
B8: IMPORTACIONES RUBI S.A. | C8: W/M | D8: PR-NTSO-20240327-0059 | E8: 2024 - RUBI - W/M - 20240403 AL 20240430 | F8: 20240403 | G8: 20240430 | H8: =SUMIF('CALCULATE (2)'!$D:$D,RESUMEN!$D8,'CALCULATE (2)'!$BA:$BA) -> 24306.55 | I8: =SUMIF('CALCULATE (2)'!$D:$D,RESUMEN!$D8,'CALCULATE (2)'!$V:$V) -> 13175.08 | J8: =+I8-H8 -> -11131.47 | K8: =+IF(J8<=0,"Retorno","Exceso") -> Retorno
B9: IMPORTACIONES RUBI S.A. | C9: W/M | D9: PR-NTSO-20240416-0006 | E9: 2024 - RUBI - W/M - 20240422 AL 20240430 | F9: 20240422 | G9: 20240430 | H9: =SUMIF('CALCULATE (2)'!$D:$D,RESUMEN!$D9,'CALCULATE (2)'!$BA:$BA) -> 9695.6 | I9: =SUMIF('CALCULATE (2)'!$D:$D,RESUMEN!$D9,'CALCULATE (2)'!$V:$V) -> 4339.02 | J9: =+I9-H9 -> -5356.58 | K9: =+IF(J9<=0,"Retorno","Exceso") -> Retorno
G10: Total | H10: =+SUBTOTAL(9,H5:H9) -> 49714.28 | I10: =+SUBTOTAL(9,I5:I9) -> 30556.36 | J10: =+SUBTOTAL(9,J5:J9) -> -19157.92
J13: Variación | K13: Retorno/Exceso
G14: =C5 -> Cooking | H14: =SUMIF($C$5:$C$9,G14,$H$5:$H$9) -> 15712.13 | I14: =SUMIF($C$5:$C$9,G14,$I$5:$I$9) -> 13042.26 | J14: =+I14-H14 -> -2669.87 | K14: =+IF(J14<=0,"Retorno","Exceso") -> Retorno
G15: W/M | H15: =SUMIF($C$5:$C$9,G15,$H$5:$H$9) -> 34002.15 | I15: =SUMIF($C$5:$C$9,G15,$I$5:$I$9) -> 17514.1 | J15: =+I15-H15 -> -16488.05 | K15: =+IF(J15<=0,"Retorno","Exceso") -> Retorno
G16: REF | H16: =SUMIF($C$5:$C$9,G16,$H$5:$H$9) -> 0 | I16: =SUMIF($C$5:$C$9,G16,$I$5:$I$9) -> 0 | J16: =+I16-H16 -> 0 | K16: =+IF(J16<=0,"Retorno","Exceso") -> Retorno
H17: =SUM(H14:H16) -> 49714.28 | I17: =SUM(I14:I16) -> 30556.36 | J17: =SUM(J14:J16) -> -19157.92

Sheet Sheet1
A3: Sum of Monto Total (Book)
A4: Customer Name | B4: Division Name | C4: Promotion No | D4: Promotion Name | E4: Fecha Inicio | F4: Fecha Fin | G4: Total
A5: IMPORTACIONES RUBI S.A. | B5: Cooking | C5: PR-NTSO-20240405-0031 | D5: 2024 - RUBI - Cooking - 20240410 AL 20240430 | E5: 20240410 | F5: 20240430 | G5: 5796.56
A6: IMPORTACIONES RUBI S.A. | B6: Cooking | C6: PR-NTSO-20240415-0011 | D6: 2024 - RUBI - Cooking - 20240420 AL 20240430 | E6: 20240420 | F6: 20240430 | G6: 0
A7: IMPORTACIONES RUBI S.A. | B7: Cooking | C7: PR-NTSO-20240416-0005 | D7: 2024 - RUBI - Cooking - 20240422 AL 20240430 | E7: 20240422 | F7: 20240430 | G7: 0
A8: IMPORTACIONES RUBI S.A. | B8: W/M | C8: PR-NTSO-20240327-0059 | D8: 2024 - RUBI - W/M - 20240403 AL 20240430 | E8: 20240403 | F8: 20240430 | G8: 13175.08
A9: IMPORTACIONES RUBI S.A. | B9: W/M | C9: PR-NTSO-20240416-0006 | D9: 2024 - RUBI - W/M - 20240422 AL 20240430 | E9: 20240422 | F9: 20240430 | G9: 4339.02
A10: Grand Total | G10: 23310.66

Sheet CALCULATE (2)
A1: Seq | B1: Company Name | C1: Division Name | D1: Promotion No | E1: Promotion Line No | F1: Fecha Inicio | G1: Fecha Fin | H1: Customer Code | I1: Modelo | J1: PVP | K1: Costo Sellin | L1: * Precio Promotion | M1: * Nuevo Margen | N1: * Costo Promocion | O1: Diferencia | P1: Unidades | Q1: * Regalo | R1: * Bundle Cost | S1: * Bundle Cost Rate | T1: Bundle Diff | U1: Bundle Unidades | V1: Monto Total (Book) | W1: Monto Total | X1: Mix Adjust Amount | Y1: * NOTE * | Z1: FCST UNIT AMT DIFF | AA1: FCST QTY DIFF | AB1: FCST AMT DIFF | AC1: * ALL / SHOP / WEB | AD1: ADDITIONAL_COND | AE1: Priority | AF1: Ref Line | AG1: Stock | AH1: Sellin in Promo | AI1: Sellout Qty | AJ1: Return Qty | AK1: Promo Applied Qty | AL1: Customer Qty | AM1: * Limit Qty | AN1: Control Over Stock | AO1: Control Not Applied | AP1: Control Cust Request | AQ1: Control Below Cost | AR1: Control Limit | AS1: Bundle Seq | AT1: Bundle Priority | AU1: Bundle Stock | AV1: Bundle Sellout | AW1: Same Model | AX1: Promotion Line Status Code | AY1: FCST Unit Amt | AZ1: FCST Qty | BA1: FCST Amt | BB1: FCST Amt(Book) | BC1: Actual Accu Qty | BD1: Actual Accu Amt | BE1: Customer Name | BF1: Promotion Name | BG1: Model Code | BH1: Currency | BI1: TC | BJ1: Line Remark | BK1: Concate
A2: 1 | B2: H&A Company | C2: Cooking | D2: PR-NTSO-20240405-0031 | E2: 1 | F2: 20240410 | G2: 20240430 | H2: PE000820001B | I2: RSG314M.FSTGLPR | J2: 0 | K2: 1944.15 | L2: 1599 | M2: 10 | N2: 1219.58 | O2: 724.57 | P2: 8 | Q2: 0 | S2: 0 | V2: 5796.56 | Z2: 0 | AA2: 0 | AB2: 0 | AC2: ALL | AE2: 1-BASIC | AG2: 18 | AH2: 0 | AI2: 18 | AJ2: 0 | AK2: 18 | AL2: 0 | AM2: 8 | AN2: 0 | AO2: 0 | AP2: 0 | AQ2: 0 | AR2: 10 | AX2: APPROVED | AY2: 724.57 | AZ2: 8 | BA2: 5796.56 | BB2: 5796.56 | BC2: 0 | BD2: 0 | BE2: IMPORTACIONES RUBI S.A. | BF2: 2024 - RUBI - Cooking - 20240410 AL 20240430 | BG2: RSG314M.FSTGLPR | BH2: PEN | BI2: 1 | BJ2: 1599_10__8 | BK2: PR-NTSO-20240405-0031RSG314M.FSTGLPR
A3: 2 | B3: H&A Company | C3: Cooking | D3: PR-NTSO-20240415-0011 | E3: 1 | F3: 20240420 | G3: 20240430 | H3: PE000820001B | I3: MS2596DIR.BBKGLPR | J3: 0 | K3: 365.34 | L3: 379 | M3: 10 | N3: 289.07 | O3: 76.27 | P3: 0 | Q3: 0 | S3: 0 | V3: 0 | Z3: 0 | AA3: -21 | AB3: -1601.67 | AC3: ALL | AE3: 1-BASIC | AG3: 24 | AH3: 0 | AI3: 0 | AJ3: 0 | AK3: 0 | AL3: 0 | AM3: 0 | AN3: 0 | AO3: 0 | AP3: 0 | AQ3: 0 | AR3: 0 | AX3: APPROVED | AY3: 76.27 | AZ3: 21 | BA3: 1601.67 | BB3: 1601.67 | BC3: 0 | BD3: 0 | BE3: IMPORTACIONES RUBI S.A. | BF3: 2024 - RUBI - Cooking - 20240420 AL 20240430 | BG3: MS2596DIR.BBKGLPR | BH3: PEN | BI3: 1 | BJ3: 379_10__ | BK3: PR-NTSO-20240415-0011MS2596DIR.BBKGLPR
A4: 3 | B4: H&A Company | C4: Cooking | D4: PR-NTSO-20240416-0005 | E4: 1 | F4: 20240422 | G4: 20240430 | H4: PE000820001B | I4: MS4296DIR.BBKGLPR | J4: 0 | K4: 433.98 | L4: 539 | M4: 10 | N4: 411.1 | O4: 22.88 | P4: 0 | Q4: 0 | S4: 0 | V4: 0 | Z4: 15.25 | AA4: -140 | AB4: -1068.2 | AC4: ALL | AE4: 1-BASIC | AG4: 49 | AH4: 0 | AI4: 0 | AJ4: 0 | AK4: 0 | AL4: 0 | AM4: 0 | AN4: 0 | AO4: 0 | AP4: 0 | AQ4: 0 | AR4: 0 | AX4: APPROVED | AY4: 7.63 | AZ4: 140 | BA4: 1068.2 | BB4: 1068.2 | BC4: 0 | BD4: 0 | BE4: IMPORTACIONES RUBI S.A. | BF4: 2024 - RUBI - Cooking - 20240422 AL 20240430 | BG4: MS4296DIR.BBKGLPR | BH4: PEN | BI4: 1 | BJ4: 539_10__ | BK4: PR-NTSO-20240416-0005MS4296DIR.BBKGLPR
A5: 4 | B5: H&A Company | C5: Cooking | D5: PR-NTSO-20240416-0005 | E5: 2 | F5: 20240422 | G5: 20240430 | H5: PE000820001B | I5: RSG314M.FSTGLPR | J5: 0 | K5: 1944.15 | L5: 1599 | M5: 10 | N5: 1219.58 | O5: 724.57 | P5: 10 | Q5: 0 | S5: 0 | V5: 7245.7 | Z5: 0 | AA5: 0 | AB5: 0 | AC5: ALL | AE5: 2-ADDITIONAL | AF5: 1 | AG5: 10 | AH5: 0 | AI5: 10 | AJ5: 0 | AK5: 10 | AL5: 0 | AM5: 0 | AN5: 0 | AO5: 0 | AP5: 0 | AQ5: 0 | AR5: 0 | AX5: APPROVED | AY5: 724.57 | AZ5: 10 | BA5: 7245.7 | BB5: 7245.7 | BC5: 0 | BD5: 0 | BE5: IMPORTACIONES RUBI S.A. | BF5: 2024 - RUBI - Cooking - 20240422 AL 20240430 | BG5: RSG314M.FSTGLPR | BH5: PEN | BI5: 1 | BJ5: 1599_10__ | BK5: PR-NTSO-20240416-0005RSG314M.FSTGLPR
A6: 5 | B6: H&A Company | C6: W/M | D6: PR-NTSO-20240327-0059 | E6: 1 | F6: 20240403 | G6: 20240430 | H6: PE000820001B | I6: WD12BVC2S6C.ABLGLGP | J6: 0 | K6: 2279.75 | L6: 2099 | M6: 10 | N6: 1600.93 | O6: 678.82 | P6: 5 | Q6: 0 | S6: 0 | V6: 3394.1 | Z6: 0 | AA6: -5 | AB6: -3394.1 | AC6: ALL | AE6: 1-BASIC | AG6: 36 | AH6: 0 | AI6: 5 | AJ6: 0 | AK6: 5 | AL6: 0 | AM6: 0 | AN6: 0 | AO6: 0 | AP6: 0 | AQ6: 0 | AR6: 0 | AX6: APPROVED | AY6: 678.82 | AZ6: 10 | BA6: 6788.2 | BB6: 6788.2 | BC6: 0 | BD6: 0 | BE6: IMPORTACIONES RUBI S.A. | BF6: 2024 - RUBI - W/M - 20240403 AL 20240430 | BG6: WD12BVC2S6C.ABLGLGP | BH6: PEN | BI6: 1 | BJ6: 2099_10__ | BK6: PR-NTSO-20240327-0059WD12BVC2S6C.ABLGLGP
A7: 6 | B7: H&A Company | C7: W/M | D7: PR-NTSO-20240327-0059 | E7: 2 | F7: 20240403 | G7: 20240430 | H7: PE000820001B | I7: WD14BVC2S6C.ABLGLGP | J7: 0 | K7: 2287.37 | L7: 2799 | M7: 10 | N7: 2134.83 | O7: 152.54 | P7: 4 | Q7: 0 | S7: 0 | V7: 610.16 | Z7: 0 | AA7: -10 | AB7: -1525.4 | AC7: ALL | AE7: 1-BASIC | AG7: 39 | AH7: 0 | AI7: 4 | AJ7: 0 | AK7: 4 | AL7: 0 | AM7: 0 | AN7: 0 | AO7: 0 | AP7: 0 | AQ7: 0 | AR7: 0 | AX7: APPROVED | AY7: 152.54 | AZ7: 14 | BA7: 2135.56 | BB7: 2135.56 | BC7: 0 | BD7: 0 | BE7: IMPORTACIONES RUBI S.A. | BF7: 2024 - RUBI - W/M - 20240403 AL 20240430 | BG7: WD14BVC2S6C.ABLGLGP | BH7: PEN | BI7: 1 | BJ7: 2799_10__ | BK7: PR-NTSO-20240327-0059WD14BVC2S6C.ABLGLGP
A8: 7 | B8: H&A Company | C8: W/M | D8: PR-NTSO-20240327-0059 | E8: 3 | F8: 20240403 | G8: 20240430 | H8: PE000820001B | I8: WD15EG2S.AESGLGP | J8: 0 | K8: 3393.31 | L8: 2949 | M8: 10 | N8: 2249.24 | O8: 1144.07 | P8: 2 | Q8: 0 | S8: 0 | V8: 2288.14 | Z8: 0 | AA8: -5 | AB8: -5720.35 | AC8: ALL | AE8: 1-BASIC | AG8: 14 | AH8: 0 | AI8: 2 | AJ8: 0 | AK8: 2 | AL8: 0 | AM8: 0 | AN8: 0 | AO8: 0 | AP8: 0 | AQ8: 0 | AR8: 0 | AX8: APPROVED | AY8: 1144.07 | AZ8: 7 | BA8: 8008.49 | BB8: 8008.49 | BC8: 0 | BD8: 0 | BE8: IMPORTACIONES RUBI S.A. | BF8: 2024 - RUBI - W/M - 20240403 AL 20240430 | BG8: WD15EG2S.AESGLGP | BH8: PEN | BI8: 1 | BJ8: 2949_10__ | BK8: PR-NTSO-20240327-0059WD15EG2S.AESGLGP
A9: 8 | B9: H&A Company | C9: W/M | D9: PR-NTSO-20240327-0059 | E9: 4 | F9: 20240403 | G9: 20240430 | H9: PE000820001B | I9: WT19BPB.ABMGLGP | J9: 0 | K9: 1372.12 | L9: 1399 | M9: 5 | N9: 1126.31 | O9: 245.81 | P9: 28 | Q9: 0 | S9: 0 | V9: 6882.68 | Z9: 0 | AA9: -2 | AB9: -491.62 | AC9: ALL | AE9: 1-BASIC | AG9: 29 | AH9: 0 | AI9: 28 | AJ9: 0 | AK9: 28 | AL9: 0 | AM9: 0 | AN9: 0 | AO9: 0 | AP9: 0 | AQ9: 0 | AR9: 0 | AX9: APPROVED | AY9: 245.81 | AZ9: 30 | BA9: 7374.3 | BB9: 7374.3 | BC9: 0 | BD9: 0 | BE9: IMPORTACIONES RUBI S.A. | BF9: 2024 - RUBI - W/M - 20240403 AL 20240430 | BG9: WT19BPB.ABMGLGP | BH9: PEN | BI9: 1 | BJ9: 1399_5__ | BK9: PR-NTSO-20240327-0059WT19BPB.ABMGLGP
A10: 9 | B10: H&A Company | C10: W/M | D10: PR-NTSO-20240416-0006 | E10: 1 | F10: 20240422 | G10: 20240430 | H10: PE000820001B | I10: WT13BPBK.ABMGLGP | J10: 0 | K10: 990.76 | L10: 1199 | M10: 10 | N10: 914.49 | O10: 76.27 | P10: 46 | Q10: 0 | S10: 0 | V10: 3508.42 | Z10: 0 | AA10: 6 | AB10: 457.62 | AC10: ALL | AE10: 1-BASIC | AG10: 101 | AH10: 0 | AI10: 46 | AJ10: 0 | AK10: 46 | AL10: 0 | AM10: 0 | AN10: 0 | AO10: 0 | AP10: 0 | AQ10: 0 | AR10: 0 | AX10: APPROVED | AY10: 76.27 | AZ10: 40 | BA10: 3050.8 | BB10: 3050.8 | BC10: 0 | BD10: 0 | BE10: IMPORTACIONES RUBI S.A. | BF10: 2024 - RUBI - W/M - 20240422 AL 20240430 | BG10: WT13BPBK.ABMGLGP | BH10: PEN | BI10: 1 | BJ10: 1199_10__ | BK10: PR-NTSO-20240416-0006WT13BPBK.ABMGLGP
A11: 10 | B11: H&A Company | C11: W/M | D11: PR-NTSO-20240416-0006 | E11: 2 | F11: 20240422 | G11: 20240430 | H11: PE000820001B | I11: WT17BV6.ABMGLGP | J11: 0 | K11: 1295.85 | L11: 1449 | M11: 8 | N11: 1129.73 | O11: 166.12 | P11: 5 | Q11: 0 | S11: 0 | V11: 830.6 | Z11: 0 | AA11: -35 | AB11: -5814.2 | AC11: ALL | AE11: 1-BASIC | AG11: 400 | AH11: 0 | AI11: 5 | AJ11: 0 | AK11: 5 | AL11: 0 | AM11: 0 | AN11: 0 | AO11: 0 | AP11: 0 | AQ11: 0 | AR11: 0 | AX11: APPROVED | AY11: 166.12 | AZ11: 40 | BA11: 6644.8 | BB11: 6644.8 | BC11: 0 | BD11: 0 | BE11: IMPORTACIONES RUBI S.A. | BF11: 2024 - RUBI - W/M - 20240422 AL 20240430 | BG11: WT17BV6.ABMGLGP | BH11: PEN | BI11: 1 | BJ11: 1449_8__ | BK11: PR-NTSO-20240416-0006WT17BV6.ABMGLGP

Sheet CALCULATE
A1: Seq | B1: Company Name | C1: Division Name | D1: Promotion No | E1: Promotion Line No | F1: Fecha Inicio | G1: Fecha Fin | H1: Customer Code | I1: Modelo | J1: PVP | K1: Costo Sellin | L1: * Precio Promotion | M1: * Nuevo Margen | N1: * Costo Promocion | O1: Diferencia | P1: Unidades | Q1: * Regalo | R1: * Bundle Cost | S1: * Bundle Cost Rate | T1: Bundle Diff | U1: Bundle Unidades | V1: Monto Total (Book) | W1: Monto Total | X1: Mix Adjust Amount | Y1: * NOTE * | Z1: FCST UNIT AMT DIFF | AA1: FCST QTY DIFF | AB1: FCST AMT DIFF | AC1: * ALL / SHOP / WEB | AD1: ADDITIONAL_COND | AE1: Priority | AF1: Ref Line | AG1: Stock | AH1: Sellin in Promo | AI1: Sellout Qty | AJ1: Return Qty | AK1: Promo Applied Qty | AL1: Customer Qty | AM1: * Limit Qty | AN1: Control Over Stock | AO1: Control Not Applied | AP1: Control Cust Request | AQ1: Control Below Cost | AR1: Control Limit | AS1: Bundle Seq | AT1: Bundle Priority | AU1: Bundle Stock | AV1: Bundle Sellout | AW1: Same Model | AX1: Promotion Line Status Code | AY1: FCST Unit Amt | AZ1: FCST Qty | BA1: FCST Amt | BB1: FCST Amt(Book) | BC1: Actual Accu Qty | BD1: Actual Accu Amt | BE1: Customer Name | BF1: Promotion Name | BG1: Model Code | BH1: Currency | BI1: TC | BJ1: Line Remark | BK1: Concate
A2: 1 | B2: H&A Company | C2: Cooking | D2: PR-NTSO-20240405-0031 | E2: 1 | F2: 20240410 | G2: 20240430 | H2: PE000820001B | I2: RSG314M.FSTGLPR | J2: 0 | K2: 1944.15 | L2: 1599 | M2: 10 | N2: 1219.58 | O2: 724.57 | P2: 8 | Q2: 0 | S2: 0 | V2: 5796.56 | Z2: 1.1368684e-13 | AA2: 0 | AB2: 9.094947e-13 | AC2: ALL | AE2: 1-BASIC | AG2: 18 | AH2: 0 | AI2: 18 | AJ2: 0 | AK2: 18 | AL2: 0 | AM2: 8 | AN2: 0 | AO2: 0 | AP2: 0 | AQ2: 0 | AR2: 10 | AX2: APPROVED | AY2: 724.57 | AZ2: 8 | BA2: 5796.56 | BB2: 5796.56 | BC2: 0 | BD2: 0 | BE2: IMPORTACIONES RUBI S.A. | BF2: 2024 - RUBI - Cooking - 20240410 AL 20240430 | BG2: RSG314M.FSTGLPR | BH2: PEN | BI2: 1 | BJ2: 1599_10__8 | BK2: PR-NTSO-20240405-0031RSG314M.FSTGLPR
A3: 2 | B3: H&A Company | C3: Cooking | D3: PR-NTSO-20240415-0011 | E3: 1 | F3: 20240420 | G3: 20240430 | H3: PE000820001B | I3: MS2596DIR.BBKGLPR | J3: 0 | K3: 365.34 | L3: 379 | M3: 10 | N3: 289.07 | O3: 76.27 | P3: 0 | Q3: 0 | S3: 0 | V3: 0 | Y3: COST UPDATED BY STOCK | Z3: -1.4210855e-14 | AA3: -21 | AB3: -1601.67 | AC3: ALL | AE3: 1-BASIC | AG3: 24 | AH3: 0 | AI3: 0 | AJ3: 0 | AK3: 0 | AL3: 0 | AM3: 0 | AN3: 0 | AO3: 0 | AP3: 0 | AQ3: 0 | AR3: 0 | AX3: APPROVED | AY3: 76.27 | AZ3: 21 | BA3: 1601.67 | BB3: 1601.67 | BC3: 0 | BD3: 0 | BE3: IMPORTACIONES RUBI S.A. | BF3: 2024 - RUBI - Cooking - 20240420 AL 20240430 | BG3: MS2596DIR.BBKGLPR | BH3: PEN | BI3: 1 | BJ3: 379_10__ | BK3: PR-NTSO-20240415-0011MS2596DIR.BBKGLPR
A4: 3 | B4: H&A Company | C4: Cooking | D4: PR-NTSO-20240416-0005 | E4: 1 | F4: 20240422 | G4: 20240430 | H4: PE000820001B | I4: MS4296DIR.BBKGLPR | J4: 0 | K4: 433.98 | L4: 539 | M4: 10 | N4: 411.1 | O4: 22.88 | P4: 0 | Q4: 0 | S4: 0 | V4: 0 | Y4: COST UPDATED BY STOCK | Z4: 15.25 | AA4: -140 | AB4: -1068.2 | AC4: ALL | AE4: 1-BASIC | AG4: 49 | AH4: 0 | AI4: 0 | AJ4: 0 | AK4: 0 | AL4: 0 | AM4: 0 | AN4: 0 | AO4: 0 | AP4: 0 | AQ4: 0 | AR4: 0 | AX4: APPROVED | AY4: 7.63 | AZ4: 140 | BA4: 1068.2 | BB4: 1068.2 | BC4: 0 | BD4: 0 | BE4: IMPORTACIONES RUBI S.A. | BF4: 2024 - RUBI - Cooking - 20240422 AL 20240430 | BG4: MS4296DIR.BBKGLPR | BH4: PEN | BI4: 1 | BJ4: 539_10__ | BK4: PR-NTSO-20240416-0005MS4296DIR.BBKGLPR
A5: 4 | B5: H&A Company | C5: Cooking | D5: PR-NTSO-20240416-0005 | E5: 2 | F5: 20240422 | G5: 20240430 | H5: PE000820001B | I5: RSG314M.FSTGLPR | J5: 0 | K5: 1219.58 | L5: 1599 | M5: 10 | N5: 1219.58 | O5: 0 | P5: 10 | Q5: 0 | S5: 0 | V5: 0 | Z5: -724.57 | AA5: 0 | AB5: -7245.7 | AC5: ALL | AE5: 2-ADDITIONAL | AF5: 1 | AG5: 10 | AH5: 0 | AI5: 10 | AJ5: 0 | AK5: 10 | AL5: 0 | AM5: 0 | AN5: 0 | AO5: 0 | AP5: 0 | AQ5: 0 | AR5: 0 | AX5: APPROVED | AY5: 724.57 | AZ5: 10 | BA5: 7245.7 | BB5: 7245.7 | BC5: 0 | BD5: 0 | BE5: IMPORTACIONES RUBI S.A. | BF5: 2024 - RUBI - Cooking - 20240422 AL 20240430 | BG5: RSG314M.FSTGLPR | BH5: PEN | BI5: 1 | BJ5: 1599_10__ | BK5: PR-NTSO-20240416-0005RSG314M.FSTGLPR
A6: 5 | B6: H&A Company | C6: W/M | D6: PR-NTSO-20240327-0059 | E6: 1 | F6: 20240403 | G6: 20240430 | H6: PE000820001B | I6: WD12BVC2S6C.ABLGLGP | J6: 0 | K6: 2279.75 | L6: 2099 | M6: 10 | N6: 1600.93 | O6: 678.82 | P6: 5 | Q6: 0 | S6: 0 | V6: 3394.1 | Z6: -1.1368684e-13 | AA6: -5 | AB6: -3394.1 | AC6: ALL | AE6: 1-BASIC | AG6: 36 | AH6: 0 | AI6: 5 | AJ6: 0 | AK6: 5 | AL6: 0 | AM6: 0 | AN6: 0 | AO6: 0 | AP6: 0 | AQ6: 0 | AR6: 0 | AX6: APPROVED | AY6: 678.82 | AZ6: 10 | BA6: 6788.2 | BB6: 6788.2 | BC6: 0 | BD6: 0 | BE6: IMPORTACIONES RUBI S.A. | BF6: 2024 - RUBI - W/M - 20240403 AL 20240430 | BG6: WD12BVC2S6C.ABLGLGP | BH6: PEN | BI6: 1 | BJ6: 2099_10__ | BK6: PR-NTSO-20240327-0059WD12BVC2S6C.ABLGLGP
A7: 6 | B7: H&A Company | C7: W/M | D7: PR-NTSO-20240327-0059 | E7: 2 | F7: 20240403 | G7: 20240430 | H7: PE000820001B | I7: WD14BVC2S6C.ABLGLGP | J7: 0 | K7: 2287.37 | L7: 2799 | M7: 10 | N7: 2134.83 | O7: 152.54 | P7: 4 | Q7: 0 | S7: 0 | V7: 610.16 | Z7: -2.8421709e-14 | AA7: -10 | AB7: -1525.4 | AC7: ALL | AE7: 1-BASIC | AG7: 39 | AH7: 0 | AI7: 4 | AJ7: 0 | AK7: 4 | AL7: 0 | AM7: 0 | AN7: 0 | AO7: 0 | AP7: 0 | AQ7: 0 | AR7: 0 | AX7: APPROVED | AY7: 152.54 | AZ7: 14 | BA7: 2135.56 | BB7: 2135.56 | BC7: 0 | BD7: 0 | BE7: IMPORTACIONES RUBI S.A. | BF7: 2024 - RUBI - W/M - 20240403 AL 20240430 | BG7: WD14BVC2S6C.ABLGLGP | BH7: PEN | BI7: 1 | BJ7: 2799_10__ | BK7: PR-NTSO-20240327-0059WD14BVC2S6C.ABLGLGP
A8: 7 | B8: H&A Company | C8: W/M | D8: PR-NTSO-20240327-0059 | E8: 3 | F8: 20240403 | G8: 20240430 | H8: PE000820001B | I8: WD15EG2S.AESGLGP | J8: 0 | K8: 3393.31 | L8: 2949 | M8: 10 | N8: 2249.24 | O8: 1144.07 | P8: 2 | Q8: 0 | S8: 0 | V8: 2288.14 | Z8: 2.2737368e-13 | AA8: -5 | AB8: -5720.35 | AC8: ALL | AE8: 1-BASIC | AG8: 14 | AH8: 0 | AI8: 2 | AJ8: 0 | AK8: 2 | AL8: 0 | AM8: 0 | AN8: 0 | AO8: 0 | AP8: 0 | AQ8: 0 | AR8: 0 | AX8: APPROVED | AY8: 1144.07 | AZ8: 7 | BA8: 8008.49 | BB8: 8008.49 | BC8: 0 | BD8: 0 | BE8: IMPORTACIONES RUBI S.A. | BF8: 2024 - RUBI - W/M - 20240403 AL 20240430 | BG8: WD15EG2S.AESGLGP | BH8: PEN | BI8: 1 | BJ8: 2949_10__ | BK8: PR-NTSO-20240327-0059WD15EG2S.AESGLGP
A9: 8 | B9: H&A Company | C9: W/M | D9: PR-NTSO-20240327-0059 | E9: 4 | F9: 20240403 | G9: 20240430 | H9: PE000820001B | I9: WT19BPB.ABMGLGP | J9: 0 | K9: 1372.12 | L9: 1399 | M9: 5 | N9: 1126.31 | O9: 245.81 | P9: 28 | Q9: 0 | S9: 0 | V9: 6882.68 | Z9: 1.7053026e-13 | AA9: -2 | AB9: -491.62 | AC9: ALL | AE9: 1-BASIC | AG9: 29 | AH9: 0 | AI9: 28 | AJ9: 0 | AK9: 28 | AL9: 0 | AM9: 0 | AN9: 0 | AO9: 0 | AP9: 0 | AQ9: 0 | AR9: 0 | AX9: APPROVED | AY9: 245.81 | AZ9: 30 | BA9: 7374.3 | BB9: 7374.3 | BC9: 0 | BD9: 0 | BE9: IMPORTACIONES RUBI S.A. | BF9: 2024 - RUBI - W/M - 20240403 AL 20240430 | BG9: WT19BPB.ABMGLGP | BH9: PEN | BI9: 1 | BJ9: 1399_5__ | BK9: PR-NTSO-20240327-0059WT19BPB.ABMGLGP
A10: 9 | B10: H&A Company | C10: W/M | D10: PR-NTSO-20240416-0006 | E10: 1 | F10: 20240422 | G10: 20240430 | H10: PE000820001B | I10: WT13BPBK.ABMGLGP | J10: 0 | K10: 990.76 | L10: 1199 | M10: 10 | N10: 914.49 | O10: 76.27 | P10: 46 | Q10: 0 | S10: 0 | V10: 3508.42 | Z10: -1.4210855e-14 | AA10: 6 | AB10: 457.62 | AC10: ALL | AE10: 1-BASIC | AG10: 101 | AH10: 0 | AI10: 46 | AJ10: 0 | AK10: 46 | AL10: 0 | AM10: 0 | AN10: 0 | AO10: 0 | AP10: 0 | AQ10: 0 | AR10: 0 | AX10: APPROVED | AY10: 76.27 | AZ10: 40 | BA10: 3050.8 | BB10: 3050.8 | BC10: 0 | BD10: 0 | BE10: IMPORTACIONES RUBI S.A. | BF10: 2024 - RUBI - W/M - 20240422 AL 20240430 | BG10: WT13BPBK.ABMGLGP | BH10: PEN | BI10: 1 | BJ10: 1199_10__ | BK10: PR-NTSO-20240416-0006WT13BPBK.ABMGLGP
A11: 10 | B11: H&A Company | C11: W/M | D11: PR-NTSO-20240416-0006 | E11: 2 | F11: 20240422 | G11: 20240430 | H11: PE000820001B | I11: WT17BV6.ABMGLGP | J11: 0 | K11: 1295.85 | L11: 1449 | M11: 8 | N11: 1129.73 | O11: 166.12 | P11: 5 | Q11: 0 | S11: 0 | V11: 830.6 | Z11: -1.1368684e-13 | AA11: -35 | AB11: -5814.2 | AC11: ALL | AE11: 1-BASIC | AG11: 400 | AH11: 0 | AI11: 5 | AJ11: 0 | AK11: 5 | AL11: 0 | AM11: 0 | AN11: 0 | AO11: 0 | AP11: 0 | AQ11: 0 | AR11: 0 | AX11: APPROVED | AY11: 166.12 | AZ11: 40 | BA11: 6644.8 | BB11: 6644.8 | BC11: 0 | BD11: 0 | BE11: IMPORTACIONES RUBI S.A. | BF11: 2024 - RUBI - W/M - 20240422 AL 20240430 | BG11: WT17BV6.ABMGLGP | BH11: PEN | BI11: 1 | BJ11: 1449_8__ | BK11: PR-NTSO-20240416-0006WT17BV6.ABMGLGP

Sheet SELLOUT
A1: CUSTOMER | B1: ACCT_GTM | C1: CUSTOMER_MODEL | D1: MODEL_CODE | E1: TXN_DATE | F1: CUST_STORE_CODE | G1: CUST_STORE_NAME | H1: SELLOUT_UNIT | I1: SELLOUT_AMT | J1: STOCK | K1: TICKET | L1: PROMO1_PRICE | M1: TARGET1_FLAG | N1: PROMO2_PRICE | O1: TARGET2_FLAG | P1: PROMO3_PRICE | Q1: TARGET3_FLAG | R1: PROMO4_PRICE | S1: TARGET4_FLAG | T1: PROMO5_PRICE | U1: TARGET5_FLAG | V1: PROMO6_PRICE | W1: TARGET6_FLAG | X1: PROMO7_PRICE | Y1: TARGET7_FLAG | Z1: PROMO8_PRICE | AA1: TARGET8_FLAG | AB1: PROMO9_PRICE | AC1: TARGET9_FLAG | AD1: PROMO10_PRICE | AE1: TARGET10_FLAG
A2: PE000820001B | B2: RUBI | C2: WD12BVC2S6C | D2: WD12BVC2S6C.ABLGLGP | E2: 45382 | J2: 36 | L2: 2099 | M2: STOCK
A3: PE000820001B | B3: RUBI | C3: WD14BVC2S6C.ABLGLGP | D3: WD14BVC2S6C.ABLGLGP | E3: 45382 | J3: 39 | L3: 2799 | M3: STOCK
A4: PE000820001B | B4: RUBI | C4: WD15EG2S | D4: WD15EG2S.AESGLGP | E4: 45382 | J4: 14 | L4: 2949 | M4: STOCK
A5: PE000820001B | B5: RUBI | C5: WT19BPB | D5: WT19BPB.ABMGLGP | E5: 45382 | J5: 29 | L5: 1399 | M5: STOCK
A6: PE000820001B | B6: RUBI | C6: WT19BPB | D6: WT19BPB.ABMGLGP | E6: 45385 | F6: 1 | G6: IMPORTACIONES RUBI LIMA | H6: 1 | I6: 1185.5932 | K6: 1399 | L6: 1399 | M6: PROMO APPLIED
A7: PE000820001B | B7: RUBI | C7: WT19BPB | D7: WT19BPB.ABMGLGP | E7: 45385 | F7: 1 | G7: IMPORTACIONES RUBI LIMA | H7: 1 | I7: 1185.5932 | K7: 1399 | L7: 1399 | M7: PROMO APPLIED
A8: PE000820001B | B8: RUBI | C8: WT19BPB | D8: WT19BPB.ABMGLGP | E8: 45385 | F8: 1 | G8: IMPORTACIONES RUBI LIMA | H8: 2 | I8: 2371.1864 | K8: 1399 | L8: 1399 | M8: PROMO APPLIED
A9: PE000820001B | B9: RUBI | C9: WD15EG2S | D9: WD15EG2S.AESGLGP | E9: 45387 | F9: 1 | G9: IMPORTACIONES RUBI LIMA | H9: 1 | I9: 2389.8305 | K9: 2820 | L9: 2949 | M9: PROMO APPLIED
A10: PE000820001B | B10: RUBI | C10: WT19BPB | D10: WT19BPB.ABMGLGP | E10: 45388 | F10: 1 | G10: IMPORTACIONES RUBI LIMA | H10: 13 | I10: 15412.712 | K10: 1399 | L10: 1399 | M10: PROMO APPLIED
A11: PE000820001B | B11: RUBI | C11: 8899552560 | D11: RSG314M.FSTGLPR | E11: 45389 | J11: 18 | L11: 1599 | M11: STOCK
A12: PE000820001B | B12: RUBI | C12: WD12BVC2S6C | D12: WD12BVC2S6C.ABLGLGP | E12: 45389 | J12: 36 | L12: 2099 | M12: STOCK
A13: PE000820001B | B13: RUBI | C13: WD14BVC2S6C.ABLGLGP | D13: WD14BVC2S6C.ABLGLGP | E13: 45389 | J13: 39 | L13: 2799 | M13: STOCK
A14: PE000820001B | B14: RUBI | C14: WD15EG2S | D14: WD15EG2S.AESGLGP | E14: 45389 | J14: 13 | L14: 2949 | M14: STOCK
A15: PE000820001B | B15: RUBI | C15: WT19BPB | D15: WT19BPB.ABMGLGP | E15: 45389 | J15: 12 | L15: 1399 | M15: STOCK
A16: PE000820001B | B16: RUBI | C16: WT19BPB | D16: WT19BPB.ABMGLGP | E16: 45390 | F16: 1 | G16: IMPORTACIONES RUBI LIMA | H16: 1 | I16: 1185.5932 | K16: 1399 | L16: 1399 | M16: PROMO APPLIED
A17: PE000820001B | B17: RUBI | C17: 8899552560 | D17: RSG314M.FSTGLPR | E17: 45394 | F17: 1 | G17: IMPORTACIONES RUBI LIMA | H17: 8 | I17: 10169.492 | K17: 1500 | L17: 1599 | M17: PROMO APPLIED
A18: PE000820001B | B18: RUBI | C18: WD14BVC2S6C.ABLGLGP | D18: WD14BVC2S6C.ABLGLGP | E18: 45394 | F18: 1 | G18: IMPORTACIONES RUBI LIMA | H18: 1 | I18: 2262.7119 | K18: 2670 | L18: 2799 | M18: PROMO APPLIED
A19: PE000820001B | B19: RUBI | C19: WT19BPB | D19: WT19BPB.ABMGLGP | E19: 45394 | F19: 1 | G19: IMPORTACIONES RUBI LIMA | H19: 1 | I19: 1185.5932 | K19: 1399 | L19: 1399 | M19: PROMO APPLIED
A20: PE000820001B | B20: RUBI | C20: WT19BPB | D20: WT19BPB.ABMGLGP | E20: 45394 | F20: 1 | G20: IMPORTACIONES RUBI LIMA | H20: 1 | I20: 1185.5932 | K20: 1399 | L20: 1399 | M20: PROMO APPLIED
A21: PE000820001B | B21: RUBI | C21: 8899552560 | D21: RSG314M.FSTGLPR | E21: 45396 | J21: 10 | L21: 1599 | M21: STOCK
A22: PE000820001B | B22: RUBI | C22: 8899552684 | D22: MS2596DIR.BBKGLPR | E22: 45396 | J22: 24 | L22: 379 | M22: STOCK
A23: PE000820001B | B23: RUBI | C23: WD12BVC2S6C | D23: WD12BVC2S6C.ABLGLGP | E23: 45396 | J23: 36 | L23: 2099 | M23: STOCK
A24: PE000820001B | B24: RUBI | C24: WD14BVC2S6C.ABLGLGP | D24: WD14BVC2S6C.ABLGLGP | E24: 45396 | J24: 38 | L24: 2799 | M24: STOCK
A25: PE000820001B | B25: RUBI | C25: WD15EG2S | D25: WD15EG2S.AESGLGP | E25: 45396 | J25: 13 | L25: 2949 | M25: STOCK
A26: PE000820001B | B26: RUBI | C26: WT19BPB | D26: WT19BPB.ABMGLGP | E26: 45396 | J26: 9 | L26: 1399 | M26: STOCK
A27: PE000820001B | B27: RUBI | C27: WD14BVC2S6C.ABLGLGP | D27: WD14BVC2S6C.ABLGLGP | E27: 45397 | F27: 2 | G27: IMPORTACIONES RUBI WEB | H27: 1 | I27: 2288.1356 | K27: 2700 | L27: 2799 | M27: PROMO APPLIED WEB
A28: PE000820001B | B28: RUBI | C28: WD14BVC2S6C.ABLGLGP | D28: WD14BVC2S6C.ABLGLGP | E28: 45397 | F28: 2 | G28: IMPORTACIONES RUBI WEB | H28: 1 | I28: 2288.1356 | K28: 2700 | L28: 2799 | M28: PROMO APPLIED WEB
A29: PE000820001B | B29: RUBI | C29: WT19BPB | D29: WT19BPB.ABMGLGP | E29: 45399 | F29: 1 | G29: IMPORTACIONES RUBI LIMA | H29: 1 | I29: 1185.5932 | K29: 1399 | L29: 1399 | M29: PROMO APPLIED
A30: PE000820001B | B30: RUBI | C30: WT19BPB | D30: WT19BPB.ABMGLGP | E30: 45399 | F30: 1 | G30: IMPORTACIONES RUBI LIMA | H30: 2 | I30: 2371.1864 | K30: 1399 | L30: 1399 | M30: PROMO APPLIED
A31: PE000820001B | B31: RUBI | C31: WD12BVC2S6C | D31: WD12BVC2S6C.ABLGLGP | E31: 45400 | F31: 1 | G31: IMPORTACIONES RUBI LIMA | H31: 1 | I31: 1694.9153 | K31: 2000.0001 | L31: 2099 | M31: PROMO APPLIED
A32: PE000820001B | B32: RUBI | C32: WD12BVC2S6C | D32: WD12BVC2S6C.ABLGLGP | E32: 45401 | F32: 1 | G32: IMPORTACIONES RUBI LIMA | H32: 1 | I32: 1694.9153 | K32: 2000.0001 | L32: 2099 | M32: PROMO APPLIED
A33: PE000820001B | B33: RUBI | C33: WD14BVC2S6C.ABLGLGP | D33: WD14BVC2S6C.ABLGLGP | E33: 45402 | F33: 2 | G33: IMPORTACIONES RUBI WEB | H33: 1 | I33: 2288.1356 | K33: 2700 | L33: 2799 | M33: PROMO APPLIED WEB
A34: PE000820001B | B34: RUBI | C34: 8899552560 | D34: RSG314M.FSTGLPR | E34: 45403 | J34: 10 | L34: 1599 | M34: STOCK
A35: PE000820001B | B35: RUBI | C35: 8899552602 | D35: MS4296DIR.BBKGLPR | E35: 45403 | J35: 49 | L35: 539 | M35: STOCK
A36: PE000820001B | B36: RUBI | C36: 8899552684 | D36: MS2596DIR.BBKGLPR | E36: 45403 | J36: 24 | L36: 379 | M36: STOCK
A37: PE000820001B | B37: RUBI | C37: WD12BVC2S6C | D37: WD12BVC2S6C.ABLGLGP | E37: 45403 | J37: 34 | L37: 2099 | M37: STOCK
A38: PE000820001B | B38: RUBI | C38: WD14BVC2S6C.ABLGLGP | D38: WD14BVC2S6C.ABLGLGP | E38: 45403 | J38: 35 | L38: 2799 | M38: STOCK
A39: PE000820001B | B39: RUBI | C39: WD15EG2S | D39: WD15EG2S.AESGLGP | E39: 45403 | J39: 13 | L39: 2949 | M39: STOCK
A40: PE000820001B | B40: RUBI | C40: WT13BPBK | D40: WT13BPBK.ABMGLGP | E40: 45403 | J40: 101 | L40: 1199 | M40: STOCK
...

Sheet SELLIN
A1: Seq | B1: Division Name | C1: Bill To Customer Code | D1: Item Name | E1: Sales YYYYMMDD | F1: Invoice NO | G1: ⁬Week-YYYYWWW | H1: Transaction Currency Code | I1: Sales Order Qty | J1: Unit Selling Price | K1: Sales Order Amount (Tax Exclude) | L1: TC | M1: Unit Selling Price (PEN) | N1: CAL SEQ1 | O1: NEW COST1 | P1: SELLOUT1 | Q1: STOCK1 | R1: CAL SEQ2 | S1: NEW COST2 | T1: SELLOUT2 | U1: STOCK2 | V1: CAL SEQ3 | W1: NEW COST3 | X1: SELLOUT3 | Y1: STOCK3 | Z1: CAL SEQ4 | AA1: NEW COST4 | AB1: SELLOUT4 | AC1: STOCK4 | AD1: CAL SEQ5 | AE1: NEW COST5 | AF1: SELLOUT5 | AG1: STOCK5 | AH1: CAL SEQ6 | AI1: NEW COST6 | AJ1: SELLOUT6 | AK1: STOCK6 | AL1: CAL SEQ7 | AM1: NEW COST7 | AN1: SELLOUT7 | AO1: STOCK7 | AP1: CAL SEQ8 | AQ1: NEW COST8 | AR1: SELLOUT8 | AS1: STOCK8 | AT1: CAL SEQ9 | AU1: NEW COST9 | AV1: SELLOUT9 | AW1: STOCK9 | AX1: CAL SEQ10 | AY1: NEW COST10 | AZ1: SELLOUT10 | BA1: STOCK10 | BB1: Bill To Customer Name | BC1: SO NO | BD1: SO Type Name
A2: 1 | B2: LTV | C2: PE000820001B | D2: MR23GN.AWP | E2: 20240424 | F2: 01-F001-00272671 | G2: 2024W13 | H2: PEN | I2: 200 | J2: 42 | K2: 8400 | L2: 3.701 | M2: 42 | N2: NA | O2: 0 | P2: 0 | Q2: 0 | R2: NA | S2: 0 | T2: 0 | U2: 0 | V2: NA | W2: 0 | X2: 0 | Y2: 0 | Z2: NA | AA2: 0 | AB2: 0 | AC2: 0 | AD2: NA | AE2: 0 | AF2: 0 | AG2: 0 | AH2: NA | AI2: 0 | AJ2: 0 | AK2: 0 | AL2: NA | AM2: 0 | AN2: 0 | AO2: 0 | AP2: NA | AQ2: 0 | AR2: 0 | AS2: 0 | AT2: NA | AU2: 0 | AV2: 0 | AW2: 0 | AX2: NA | AY2: 0 | AZ2: 0 | BA2: 0 | BB2: IMPORTACIONES RUBI S.A. | BC2: 1000442117 | BD2: REGULAR_OMD_PR
A3: 2 | B3: LTV | C3: PE000820001B | D3: MR23GN.AWP | E3: 20240228 | F3: 01-F001-00270000 | G3: 2024W08 | H3: PEN | I3: 79 | J3: 42 | K3: 3318 | L3: 3.793 | M3: 42 | N3: NA | O3: 0 | P3: 0 | Q3: 0 | R3: NA | S3: 0 | T3: 0 | U3: 0 | V3: NA | W3: 0 | X3: 0 | Y3: 0 | Z3: NA | AA3: 0 | AB3: 0 | AC3: 0 | AD3: NA | AE3: 0 | AF3: 0 | AG3: 0 | AH3: NA | AI3: 0 | AJ3: 0 | AK3: 0 | AL3: NA | AM3: 0 | AN3: 0 | AO3: 0 | AP3: NA | AQ3: 0 | AR3: 0 | AS3: 0 | AT3: NA | AU3: 0 | AV3: 0 | AW3: 0 | AX3: NA | AY3: 0 | AZ3: 0 | BA3: 0 | BB3: IMPORTACIONES RUBI S.A. | BC3: 1000439943 | BD3: REGULAR_OMD_PR
A4: 3 | B4: LTV | C4: PE000820001B | D4: MR23GN.AWP | E4: 20240228 | F4: 01-F001-00269999 | G4: 2024W04 | H4: PEN | I4: 100 | J4: 42 | K4: 4200 | L4: 3.793 | M4: 42 | N4: NA | O4: 0 | P4: 0 | Q4: 0 | R4: NA | S4: 0 | T4: 0 | U4: 0 | V4: NA | W4: 0 | X4: 0 | Y4: 0 | Z4: NA | AA4: 0 | AB4: 0 | AC4: 0 | AD4: NA | AE4: 0 | AF4: 0 | AG4: 0 | AH4: NA | AI4: 0 | AJ4: 0 | AK4: 0 | AL4: NA | AM4: 0 | AN4: 0 | AO4: 0 | AP4: NA | AQ4: 0 | AR4: 0 | AS4: 0 | AT4: NA | AU4: 0 | AV4: 0 | AW4: 0 | AX4: NA | AY4: 0 | AZ4: 0 | BA4: 0 | BB4: IMPORTACIONES RUBI S.A. | BC4: 1000438256 | BD4: REGULAR_OMD_PR
A5: 4 | B5: LTV | C5: PE000820001B | D5: MR23GN.AWP | E5: 20240227 | F5: 01-F001-00269910 | G5: 2024W04 | H5: PEN | I5: 200 | J5: 42 | K5: 8400 | L5: 3.803 | M5: 42 | N5: NA | O5: 0 | P5: 0 | Q5: 0 | R5: NA | S5: 0 | T5: 0 | U5: 0 | V5: NA | W5: 0 | X5: 0 | Y5: 0 | Z5: NA | AA5: 0 | AB5: 0 | AC5: 0 | AD5: NA | AE5: 0 | AF5: 0 | AG5: 0 | AH5: NA | AI5: 0 | AJ5: 0 | AK5: 0 | AL5: NA | AM5: 0 | AN5: 0 | AO5: 0 | AP5: NA | AQ5: 0 | AR5: 0 | AS5: 0 | AT5: NA | AU5: 0 | AV5: 0 | AW5: 0 | AX5: NA | AY5: 0 | AZ5: 0 | BA5: 0 | BB5: IMPORTACIONES RUBI S.A. | BC5: 1000438256 | BD5: REGULAR_OMD_PR
A6: 5 | B6: LTV | C6: PE000820001B | D6: MR23GN.AWP | E6: 20231027 | G6: 2023W43 | H6: PEN | I6: 100 | J6: 42 | K6: 4200 | L6: 3.872 | M6: 42 | N6: NA | O6: 0 | P6: 0 | Q6: 0 | R6: NA | S6: 0 | T6: 0 | U6: 0 | V6: NA | W6: 0 | X6: 0 | Y6: 0 | Z6: NA | AA6: 0 | AB6: 0 | AC6: 0 | AD6: NA | AE6: 0 | AF6: 0 | AG6: 0 | AH6: NA | AI6: 0 | AJ6: 0 | AK6: 0 | AL6: NA | AM6: 0 | AN6: 0 | AO6: 0 | AP6: NA | AQ6: 0 | AR6: 0 | AS6: 0 | AT6: NA | AU6: 0 | AV6: 0 | AW6: 0 | AX6: NA | AY6: 0 | AZ6: 0 | BA6: 0 | BB6: IMPORTACIONES RUBI S.A. | BC6: 1000433957 | BD6: REGULAR_OMD_PR
A7: 6 | B7: LTV | C7: PE000820001B | D7: MR23GN.AWP | E7: 20231027 | G7: 2023W43 | H7: PEN | I7: 200 | J7: 42 | K7: 8400 | L7: 3.872 | M7: 42 | N7: NA | O7: 0 | P7: 0 | Q7: 0 | R7: NA | S7: 0 | T7: 0 | U7: 0 | V7: NA | W7: 0 | X7: 0 | Y7: 0 | Z7: NA | AA7: 0 | AB7: 0 | AC7: 0 | AD7: NA | AE7: 0 | AF7: 0 | AG7: 0 | AH7: NA | AI7: 0 | AJ7: 0 | AK7: 0 | AL7: NA | AM7: 0 | AN7: 0 | AO7: 0 | AP7: NA | AQ7: 0 | AR7: 0 | AS7: 0 | AT7: NA | AU7: 0 | AV7: 0 | AW7: 0 | AX7: NA | AY7: 0 | AZ7: 0 | BA7: 0 | BB7: IMPORTACIONES RUBI S.A. | BC7: 1000433957 | BD7: REGULAR_OMD_PR
A8: 7 | B8: LTV | C8: PE000820001B | D8: MR23GN.AWP | E8: 20230930 | G8: 2023W39 | H8: PEN | I8: 50 | J8: 42 | K8: 2100 | L8: 3.797 | M8: 42 | N8: NA | O8: 0 | P8: 0 | Q8: 0 | R8: NA | S8: 0 | T8: 0 | U8: 0 | V8: NA | W8: 0 | X8: 0 | Y8: 0 | Z8: NA | AA8: 0 | AB8: 0 | AC8: 0 | AD8: NA | AE8: 0 | AF8: 0 | AG8: 0 | AH8: NA | AI8: 0 | AJ8: 0 | AK8: 0 | AL8: NA | AM8: 0 | AN8: 0 | AO8: 0 | AP8: NA | AQ8: 0 | AR8: 0 | AS8: 0 | AT8: NA | AU8: 0 | AV8: 0 | AW8: 0 | AX8: NA | AY8: 0 | AZ8: 0 | BA8: 0 | BB8: IMPORTACIONES RUBI S.A. | BC8: 1000432944 | BD8: REGULAR_OMD_PR
A9: 8 | B9: LTV | C9: PE000820001B | D9: MR23GN.AWP | E9: 20230929 | G9: 2023W39 | H9: PEN | I9: 100 | J9: 42 | K9: 4200 | L9: 3.806 | M9: 42 | N9: NA | O9: 0 | P9: 0 | Q9: 0 | R9: NA | S9: 0 | T9: 0 | U9: 0 | V9: NA | W9: 0 | X9: 0 | Y9: 0 | Z9: NA | AA9: 0 | AB9: 0 | AC9: 0 | AD9: NA | AE9: 0 | AF9: 0 | AG9: 0 | AH9: NA | AI9: 0 | AJ9: 0 | AK9: 0 | AL9: NA | AM9: 0 | AN9: 0 | AO9: 0 | AP9: NA | AQ9: 0 | AR9: 0 | AS9: 0 | AT9: NA | AU9: 0 | AV9: 0 | AW9: 0 | AX9: NA | AY9: 0 | AZ9: 0 | BA9: 0 | BB9: IMPORTACIONES RUBI S.A. | BC9: 1000432889 | BD9: REGULAR_OMD_PR
A10: 9 | B10: Cooking | C10: PE000820001B | D10: MS2596DIR.BBKGLPR | E10: 20230527 | F10: 01-F001-00257299 | G10: 2023W21 | H10: PEN | I10: 50 | J10: 365.34 | K10: 18267 | L10: 3.675 | M10: 365.34 | N10: 2 | O10: 365.34 | P10: 0 | Q10: 24 | R10: NA | S10: 0 | T10: 0 | U10: 0 | V10: NA | W10: 0 | X10: 0 | Y10: 0 | Z10: NA | AA10: 0 | AB10: 0 | AC10: 0 | AD10: NA | AE10: 0 | AF10: 0 | AG10: 0 | AH10: NA | AI10: 0 | AJ10: 0 | AK10: 0 | AL10: NA | AM10: 0 | AN10: 0 | AO10: 0 | AP10: NA | AQ10: 0 | AR10: 0 | AS10: 0 | AT10: NA | AU10: 0 | AV10: 0 | AW10: 0 | AX10: NA | AY10: 0 | AZ10: 0 | BA10: 0 | BB10: IMPORTACIONES RUBI S.A. | BC10: 1000427925 | BD10: REGULAR_OMD_PR
A11: 10 | B11: Cooking | C11: PE000820001B | D11: MS2596DIR.BBKGLPR | E11: 20230223 | G11: 2023W02 | H11: PEN | I11: 15 | J11: 365.34 | K11: 5480.1 | L11: 3.827 | M11: 365.34 | N11: NA | O11: 0 | P11: 0 | Q11: 0 | R11: NA | S11: 0 | T11: 0 | U11: 0 | V11: NA | W11: 0 | X11: 0 | Y11: 0 | Z11: NA | AA11: 0 | AB11: 0 | AC11: 0 | AD11: NA | AE11: 0 | AF11: 0 | AG11: 0 | AH11: NA | AI11: 0 | AJ11: 0 | AK11: 0 | AL11: NA | AM11: 0 | AN11: 0 | AO11: 0 | AP11: NA | AQ11: 0 | AR11: 0 | AS11: 0 | AT11: NA | AU11: 0 | AV11: 0 | AW11: 0 | AX11: NA | AY11: 0 | AZ11: 0 | BA11: 0 | BB11: IMPORTACIONES RUBI S.A. | BC11: 1000422908 | BD11: REGULAR_OMD_PR
A12: 11 | B12: Cooking | C12: PE000820001B | D12: MS2596DIR.BBKGLPR | E12: 20230203 | G12: 2022W50 | H12: PEN | I12: 15 | J12: 365.34 | K12: 5480.1 | L12: 3.835 | M12: 365.34 | N12: NA | O12: 0 | P12: 0 | Q12: 0 | R12: NA | S12: 0 | T12: 0 | U12: 0 | V12: NA | W12: 0 | X12: 0 | Y12: 0 | Z12: NA | AA12: 0 | AB12: 0 | AC12: 0 | AD12: NA | AE12: 0 | AF12: 0 | AG12: 0 | AH12: NA | AI12: 0 | AJ12: 0 | AK12: 0 | AL12: NA | AM12: 0 | AN12: 0 | AO12: 0 | AP12: NA | AQ12: 0 | AR12: 0 | AS12: 0 | AT12: NA | AU12: 0 | AV12: 0 | AW12: 0 | AX12: NA | AY12: 0 | AZ12: 0 | BA12: 0 | BB12: IMPORTACIONES RUBI S.A. | BC12: 1000422292 | BD12: REGULAR_OMD_PR
A13: 12 | B13: Cooking | C13: PE000820001B | D13: MS2596DIR.BBKGLPR | E13: 20230131 | F13: 01-F001-00251305 | G13: 2022W50 | H13: PEN | I13: 3 | J13: 365.34 | K13: 1096.02 | L13: 3.859 | M13: 365.34 | N13: NA | O13: 0 | P13: 0 | Q13: 0 | R13: NA | S13: 0 | T13: 0 | U13: 0 | V13: NA | W13: 0 | X13: 0 | Y13: 0 | Z13: NA | AA13: 0 | AB13: 0 | AC13: 0 | AD13: NA | AE13: 0 | AF13: 0 | AG13: 0 | AH13: NA | AI13: 0 | AJ13: 0 | AK13: 0 | AL13: NA | AM13: 0 | AN13: 0 | AO13: 0 | AP13: NA | AQ13: 0 | AR13: 0 | AS13: 0 | AT13: NA | AU13: 0 | AV13: 0 | AW13: 0 | AX13: NA | AY13: 0 | AZ13: 0 | BA13: 0 | BB13: IMPORTACIONES RUBI S.A. | BC13: 1000422292 | BD13: REGULAR_OMD_PR
A14: 13 | B14: Cooking | C14: PE000820001B | D14: MS2596DIR.BBKGLPR | E14: 20230126 | G14: 2022W50 | H14: PEN | I14: 2 | J14: 365.34 | K14: 730.68 | L14: 3.9 | M14: 365.34 | N14: NA | O14: 0 | P14: 0 | Q14: 0 | R14: NA | S14: 0 | T14: 0 | U14: 0 | V14: NA | W14: 0 | X14: 0 | Y14: 0 | Z14: NA | AA14: 0 | AB14: 0 | AC14: 0 | AD14: NA | AE14: 0 | AF14: 0 | AG14: 0 | AH14: NA | AI14: 0 | AJ14: 0 | AK14: 0 | AL14: NA | AM14: 0 | AN14: 0 | AO14: 0 | AP14: NA | AQ14: 0 | AR14: 0 | AS14: 0 | AT14: NA | AU14: 0 | AV14: 0 | AW14: 0 | AX14: NA | AY14: 0 | AZ14: 0 | BA14: 0 | BB14: IMPORTACIONES RUBI S.A. | BC14: 1000422292 | BD14: REGULAR_OMD_PR
A15: 14 | B15: Cooking | C15: PE000820001B | D15: MS2596DIR.BBKGLPR | E15: 20221222 | F15: 01-F001-00249968 | G15: 2022W50 | H15: PEN | I15: 20 | J15: 365.34 | K15: 7306.8 | L15: 3.825 | M15: 365.34 | N15: NA | O15: 0 | P15: 0 | Q15: 0 | R15: NA | S15: 0 | T15: 0 | U15: 0 | V15: NA | W15: 0 | X15: 0 | Y15: 0 | Z15: NA | AA15: 0 | AB15: 0 | AC15: 0 | AD15: NA | AE15: 0 | AF15: 0 | AG15: 0 | AH15: NA | AI15: 0 | AJ15: 0 | AK15: 0 | AL15: NA | AM15: 0 | AN15: 0 | AO15: 0 | AP15: NA | AQ15: 0 | AR15: 0 | AS15: 0 | AT15: NA | AU15: 0 | AV15: 0 | AW15: 0 | AX15: NA | AY15: 0 | AZ15: 0 | BA15: 0 | BB15: IMPORTACIONES RUBI S.A. | BC15: 1000422292 | BD15: REGULAR_OMD_PR
A16: 15 | B16: Cooking | C16: PE000820001B | D16: MS2596DIR.BBKGLPR | E16: 20220408 | G16: 2022W12 | H16: PEN | I16: 50 | J16: 357.71 | K16: 17885.5 | L16: 3.714 | M16: 357.71 | N16: NA | O16: 0 | P16: 0 | Q16: 0 | R16: NA | S16: 0 | T16: 0 | U16: 0 | V16: NA | W16: 0 | X16: 0 | Y16: 0 | Z16: NA | AA16: 0 | AB16: 0 | AC16: 0 | AD16: NA | AE16: 0 | AF16: 0 | AG16: 0 | AH16: NA | AI16: 0 | AJ16: 0 | AK16: 0 | AL16: NA | AM16: 0 | AN16: 0 | AO16: 0 | AP16: NA | AQ16: 0 | AR16: 0 | AS16: 0 | AT16: NA | AU16: 0 | AV16: 0 | AW16: 0 | AX16: NA | AY16: 0 | AZ16: 0 | BA16: 0 | BB16: IMPORTACIONES RUBI S.A. | BC16: 1000414682 | BD16: REGULAR_OMD_PR
A17: 16 | B17: Cooking | C17: PE000820001B | D17: MS2596DIR.BBKGLPR | E17: 20220408 | G17: 2022W14 | H17: PEN | I17: -1 | J17: 357.71 | K17: -357.71 | L17: 3.714 | M17: 357.71 | N17: NA | O17: 0 | P17: 0 | Q17: 0 | R17: NA | S17: 0 | T17: 0 | U17: 0 | V17: NA | W17: 0 | X17: 0 | Y17: 0 | Z17: NA | AA17: 0 | AB17: 0 | AC17: 0 | AD17: NA | AE17: 0 | AF17: 0 | AG17: 0 | AH17: NA | AI17: 0 | AJ17: 0 | AK17: 0 | AL17: NA | AM17: 0 | AN17: 0 | AO17: 0 | AP17: NA | AQ17: 0 | AR17: 0 | AS17: 0 | AT17: NA | AU17: 0 | AV17: 0 | AW17: 0 | AX17: NA | AY17: 0 | AZ17: 0 | BA17: 0 | BB17: IMPORTACIONES RUBI S.A. | BC17: 3000025867 | BD17: GOODSET_RETURN_OMD_PR
A18: 17 | B18: Cooking | C18: PE000820001B | D18: MS2596DIR.BBKGLPR | E18: 20220120 | G18: 2022W02 | H18: PEN | I18: 5 | J18: 388.22 | K18: 1941.1 | L18: 3.866 | M18: 388.22 | N18: NA | O18: 0 | P18: 0 | Q18: 0 | R18: NA | S18: 0 | T18: 0 | U18: 0 | V18: NA | W18: 0 | X18: 0 | Y18: 0 | Z18: NA | AA18: 0 | AB18: 0 | AC18: 0 | AD18: NA | AE18: 0 | AF18: 0 | AG18: 0 | AH18: NA | AI18: 0 | AJ18: 0 | AK18: 0 | AL18: NA | AM18: 0 | AN18: 0 | AO18: 0 | AP18: NA | AQ18: 0 | AR18: 0 | AS18: 0 | AT18: NA | AU18: 0 | AV18: 0 | AW18: 0 | AX18: NA | AY18: 0 | AZ18: 0 | BA18: 0 | BB18: IMPORTACIONES RUBI S.A. | BC18: 1000412314 | BD18: REGULAR_OMD_PR
A19: 18 | B19: Cooking | C19: PE000820001B | D19: MS2596DIR.BBKGLPR | E19: 20211127 | G19: 2021W45 | H19: PEN | I19: 2 | J19: 372.97 | K19: 745.94 | L19: 4.041 | M19: 372.97 | N19: NA | O19: 0 | P19: 0 | Q19: 0 | R19: NA | S19: 0 | T19: 0 | U19: 0 | V19: NA | W19: 0 | X19: 0 | Y19: 0 | Z19: NA | AA19: 0 | AB19: 0 | AC19: 0 | AD19: NA | AE19: 0 | AF19: 0 | AG19: 0 | AH19: NA | AI19: 0 | AJ19: 0 | AK19: 0 | AL19: NA | AM19: 0 | AN19: 0 | AO19: 0 | AP19: NA | AQ19: 0 | AR19: 0 | AS19: 0 | AT19: NA | AU19: 0 | AV19: 0 | AW19: 0 | AX19: NA | AY19: 0 | AZ19: 0 | BA19: 0 | BB19: IMPORTACIONES RUBI S.A. | BC19: 1000410428 | BD19: REGULAR_OMD_PR
A20: 19 | B20: Cooking | C20: PE000820001B | D20: MS2596DIR.BBKGLPR | E20: 20211126 | G20: 2021W47 | H20: PEN | I20: 7 | J20: 372.97 | K20: 2610.79 | L20: 4.031 | M20: 372.97 | N20: NA | O20: 0 | P20: 0 | Q20: 0 | R20: NA | S20: 0 | T20: 0 | U20: 0 | V20: NA | W20: 0 | X20: 0 | Y20: 0 | Z20: NA | AA20: 0 | AB20: 0 | AC20: 0 | AD20: NA | AE20: 0 | AF20: 0 | AG20: 0 | AH20: NA | AI20: 0 | AJ20: 0 | AK20: 0 | AL20: NA | AM20: 0 | AN20: 0 | AO20: 0 | AP20: NA | AQ20: 0 | AR20: 0 | AS20: 0 | AT20: NA | AU20: 0 | AV20: 0 | AW20: 0 | AX20: NA | AY20: 0 | AZ20: 0 | BA20: 0 | BB20: IMPORTACIONES RUBI S.A. | BC20: 1000410826 | BD20: REGULAR_OMD_PR
A21: 20 | B21: Cooking | C21: PE000820001B | D21: MS2596DIR.BBKGLPR | E21: 20211126 | F21: 01-F001-00230214 | G21: 2021W43 | H21: PEN | I21: 8 | J21: 372.97 | K21: 2983.76 | L21: 4.031 | M21: 372.97 | N21: NA | O21: 0 | P21: 0 | Q21: 0 | R21: NA | S21: 0 | T21: 0 | U21: 0 | V21: NA | W21: 0 | X21: 0 | Y21: 0 | Z21: NA | AA21: 0 | AB21: 0 | AC21: 0 | AD21: NA | AE21: 0 | AF21: 0 | AG21: 0 | AH21: NA | AI21: 0 | AJ21: 0 | AK21: 0 | AL21: NA | AM21: 0 | AN21: 0 | AO21: 0 | AP21: NA | AQ21: 0 | AR21: 0 | AS21: 0 | AT21: NA | AU21: 0 | AV21: 0 | AW21: 0 | AX21: NA | AY21: 0 | AZ21: 0 | BA21: 0 | BB21: IMPORTACIONES RUBI S.A. | BC21: 1000410134 | BD21: REGULAR_OMD_PR
A22: 21 | B22: Cooking | C22: PE000820001B | D22: MS2596DIR.BBKGLPR | E22: 20211126 | F22: 01-F001-00230196 | G22: 2021W44 | H22: PEN | I22: 8 | J22: 372.97 | K22: 2983.76 | L22: 4.031 | M22: 372.97 | N22: NA | O22: 0 | P22: 0 | Q22: 0 | R22: NA | S22: 0 | T22: 0 | U22: 0 | V22: NA | W22: 0 | X22: 0 | Y22: 0 | Z22: NA | AA22: 0 | AB22: 0 | AC22: 0 | AD22: NA | AE22: 0 | AF22: 0 | AG22: 0 | AH22: NA | AI22: 0 | AJ22: 0 | AK22: 0 | AL22: NA | AM22: 0 | AN22: 0 | AO22: 0 | AP22: NA | AQ22: 0 | AR22: 0 | AS22: 0 | AT22: NA | AU22: 0 | AV22: 0 | AW22: 0 | AX22: NA | AY22: 0 | AZ22: 0 | BA22: 0 | BB22: IMPORTACIONES RUBI S.A. | BC22: 1000410406 | BD22: REGULAR_OMD_PR
A23: 22 | B23: Cooking | C23: PE000820001B | D23: MS2596DIR.BBKGLPR | E23: 20210925 | F23: 01-F001-00226125 | G23: 2021W38 | H23: PEN | I23: 10 | J23: 372.97 | K23: 3729.7 | L23: 4.111 | M23: 372.97 | N23: NA | O23: 0 | P23: 0 | Q23: 0 | R23: NA | S23: 0 | T23: 0 | U23: 0 | V23: NA | W23: 0 | X23: 0 | Y23: 0 | Z23: NA | AA23: 0 | AB23: 0 | AC23: 0 | AD23: NA | AE23: 0 | AF23: 0 | AG23: 0 | AH23: NA | AI23: 0 | AJ23: 0 | AK23: 0 | AL23: NA | AM23: 0 | AN23: 0 | AO23: 0 | AP23: NA | AQ23: 0 | AR23: 0 | AS23: 0 | AT23: NA | AU23: 0 | AV23: 0 | AW23: 0 | AX23: NA | AY23: 0 | AZ23: 0 | BA23: 0 | BB23: IMPORTACIONES RUBI S.A. | BC23: 1000409085 | BD23: REGULAR_OMD_PR
A24: 23 | B24: Cooking | C24: PE000820001B | D24: MS2596DIR.BBKGLPR | E24: 20210311 | G24: 2021W10 | H24: PEN | I24: 5 | J24: 327.2 | K24: 1636 | L24: 3.696 | M24: 327.2 | N24: NA | O24: 0 | P24: 0 | Q24: 0 | R24: NA | S24: 0 | T24: 0 | U24: 0 | V24: NA | W24: 0 | X24: 0 | Y24: 0 | Z24: NA | AA24: 0 | AB24: 0 | AC24: 0 | AD24: NA | AE24: 0 | AF24: 0 | AG24: 0 | AH24: NA | AI24: 0 | AJ24: 0 | AK24: 0 | AL24: NA | AM24: 0 | AN24: 0 | AO24: 0 | AP24: NA | AQ24: 0 | AR24: 0 | AS24: 0 | AT24: NA | AU24: 0 | AV24: 0 | AW24: 0 | AX24: NA | AY24: 0 | AZ24: 0 | BA24: 0 | BB24: IMPORTACIONES RUBI S.A. | BC24: 1000403660 | BD24: REGULAR_OMD_PR
A25: 24 | B25: Cooking | C25: PE000820001B | D25: MS2596DIR.BBKGLPR | E25: 20210219 | G25: 2021W02 | H25: PEN | I25: 3 | J25: 334.83 | K25: 1004.49 | L25: 3.652 | M25: 334.83 | N25: NA | O25: 0 | P25: 0 | Q25: 0 | R25: NA | S25: 0 | T25: 0 | U25: 0 | V25: NA | W25: 0 | X25: 0 | Y25: 0 | Z25: NA | AA25: 0 | AB25: 0 | AC25: 0 | AD25: NA | AE25: 0 | AF25: 0 | AG25: 0 | AH25: NA | AI25: 0 | AJ25: 0 | AK25: 0 | AL25: NA | AM25: 0 | AN25: 0 | AO25: 0 | AP25: NA | AQ25: 0 | AR25: 0 | AS25: 0 | AT25: NA | AU25: 0 | AV25: 0 | AW25: 0 | AX25: NA | AY25: 0 | AZ25: 0 | BA25: 0 | BB25: IMPORTACIONES RUBI S.A. | BC25: 1000401569 | BD25: REGULAR_OMD_PR
A26: 25 | B26: Cooking | C26: PE000820001B | D26: MS2596DIR.BBKGLPR | E26: 20210219 | G26: 2021W02 | H26: PEN | I26: 10 | J26: 334.83 | K26: 3348.3 | L26: 3.652 | M26: 334.83 | N26: NA | O26: 0 | P26: 0 | Q26: 0 | R26: NA | S26: 0 | T26: 0 | U26: 0 | V26: NA | W26: 0 | X26: 0 | Y26: 0 | Z26: NA | AA26: 0 | AB26: 0 | AC26: 0 | AD26: NA | AE26: 0 | AF26: 0 | AG26: 0 | AH26: NA | AI26: 0 | AJ26: 0 | AK26: 0 | AL26: NA | AM26: 0 | AN26: 0 | AO26: 0 | AP26: NA | AQ26: 0 | AR26: 0 | AS26: 0 | AT26: NA | AU26: 0 | AV26: 0 | AW26: 0 | AX26: NA | AY26: 0 | AZ26: 0 | BA26: 0 | BB26: IMPORTACIONES RUBI S.A. | BC26: 1000401573 | BD26: REGULAR_OMD_PR
A27: 26 | B27: Cooking | C27: PE000820001B | D27: MS2596DIR.BBKGLPR | E27: 20210218 | G27: 2021W02 | H27: PEN | I27: 2 | J27: 334.83 | K27: 669.66 | L27: 3.655 | M27: 334.83 | N27: NA | O27: 0 | P27: 0 | Q27: 0 | R27: NA | S27: 0 | T27: 0 | U27: 0 | V27: NA | W27: 0 | X27: 0 | Y27: 0 | Z27: NA | AA27: 0 | AB27: 0 | AC27: 0 | AD27: NA | AE27: 0 | AF27: 0 | AG27: 0 | AH27: NA | AI27: 0 | AJ27: 0 | AK27: 0 | AL27: NA | AM27: 0 | AN27: 0 | AO27: 0 | AP27: NA | AQ27: 0 | AR27: 0 | AS27: 0 | AT27: NA | AU27: 0 | AV27: 0 | AW27: 0 | AX27: NA | AY27: 0 | AZ27: 0 | BA27: 0 | BB27: IMPORTACIONES RUBI S.A. | BC27: 1000401647 | BD27: REGULAR_OMD_PR
A28: 27 | B28: Cooking | C28: PE000820001B | D28: MS2596DIR.BBKGLPR | E28: 20210116 | F28: 01-F001-00205073 | G28: 2020W46 | H28: PEN | I28: 1 | J28: 327.2 | K28: 327.2 | L28: 3.614 | M28: 327.2 | N28: NA | O28: 0 | P28: 0 | Q28: 0 | R28: NA | S28: 0 | T28: 0 | U28: 0 | V28: NA | W28: 0 | X28: 0 | Y28: 0 | Z28: NA | AA28: 0 | AB28: 0 | AC28: 0 | AD28: NA | AE28: 0 | AF28: 0 | AG28: 0 | AH28: NA | AI28: 0 | AJ28: 0 | AK28: 0 | AL28: NA | AM28: 0 | AN28: 0 | AO28: 0 | AP28: NA | AQ28: 0 | AR28: 0 | AS28: 0 | AT28: NA | AU28: 0 | AV28: 0 | AW28: 0 | AX28: NA | AY28: 0 | AZ28: 0 | BA28: 0 | BB28: IMPORTACIONES RUBI S.A. | BC28: 1000399718 | BD28: REGULAR_OMD_PR
A29: 28 | B29: Cooking | C29: PE000820001B | D29: MS2596DIR.BBKGLPR | E29: 20210116 | F29: 01-F001-00205058 | G29: 2020W46 | H29: PEN | I29: 1 | J29: 327.2 | K29: 327.2 | L29: 3.614 | M29: 327.2 | N29: NA | O29: 0 | P29: 0 | Q29: 0 | R29: NA | S29: 0 | T29: 0 | U29: 0 | V29: NA | W29: 0 | X29: 0 | Y29: 0 | Z29: NA | AA29: 0 | AB29: 0 | AC29: 0 | AD29: NA | AE29: 0 | AF29: 0 | AG29: 0 | AH29: NA | AI29: 0 | AJ29: 0 | AK29: 0 | AL29: NA | AM29: 0 | AN29: 0 | AO29: 0 | AP29: NA | AQ29: 0 | AR29: 0 | AS29: 0 | AT29: NA | AU29: 0 | AV29: 0 | AW29: 0 | AX29: NA | AY29: 0 | AZ29: 0 | BA29: 0 | BB29: IMPORTACIONES RUBI S.A. | BC29: 1000399636 | BD29: REGULAR_OMD_PR
A30: 29 | B30: Cooking | C30: PE000820001B | D30: MS4296DIR.BBKGLPR | E30: 20240227 | G30: 2024W08 | H30: PEN | I30: 5 | J30: 418.73 | K30: 2093.65 | L30: 3.803 | M30: 418.73 | N30: 3 | O30: 433.98 | Q30: 5 | R30: NA | S30: 0 | T30: 0 | U30: 0 | V30: NA | W30: 0 | X30: 0 | Y30: 0 | Z30: NA | AA30: 0 | AB30: 0 | AC30: 0 | AD30: NA | AE30: 0 | AF30: 0 | AG30: 0 | AH30: NA | AI30: 0 | AJ30: 0 | AK30: 0 | AL30: NA | AM30: 0 | AN30: 0 | AO30: 0 | AP30: NA | AQ30: 0 | AR30: 0 | AS30: 0 | AT30: NA | AU30: 0 | AV30: 0 | AW30: 0 | AX30: NA | AY30: 0 | AZ30: 0 | BA30: 0 | BB30: IMPORTACIONES RUBI S.A. | BC30: 1000439898 | BD30: REGULAR_OMD_PR
A31: 30 | B31: Cooking | C31: PE000820001B | D31: MS4296DIR.BBKGLPR | E31: 20230727 | F31: 01-F001-00259861 | G31: 2023W21 | H31: PEN | I31: 48 | J31: 433.98 | K31: 20831.04 | L31: 3.602 | M31: 433.98 | N31: 3 | O31: 433.98 | P31: 0 | Q31: 44 | R31: NA | S31: 0 | T31: 0 | U31: 0 | V31: NA | W31: 0 | X31: 0 | Y31: 0 | Z31: NA | AA31: 0 | AB31: 0 | AC31: 0 | AD31: NA | AE31: 0 | AF31: 0 | AG31: 0 | AH31: NA | AI31: 0 | AJ31: 0 | AK31: 0 | AL31: NA | AM31: 0 | AN31: 0 | AO31: 0 | AP31: NA | AQ31: 0 | AR31: 0 | AS31: 0 | AT31: NA | AU31: 0 | AV31: 0 | AW31: 0 | AX31: NA | AY31: 0 | AZ31: 0 | BA31: 0 | BB31: IMPORTACIONES RUBI S.A. | BC31: 1000427925 | BD31: REGULAR_OMD_PR
A32: 31 | B32: Cooking | C32: PE000820001B | D32: MS4296DIR.BBKGLPR | E32: 20230527 | G32: 2023W21 | H32: PEN | I32: 4 | J32: 433.98 | K32: 1735.92 | L32: 3.675 | M32: 433.98 | N32: NA | O32: 0 | P32: 0 | Q32: 0 | R32: NA | S32: 0 | T32: 0 | U32: 0 | V32: NA | W32: 0 | X32: 0 | Y32: 0 | Z32: NA | AA32: 0 | AB32: 0 | AC32: 0 | AD32: NA | AE32: 0 | AF32: 0 | AG32: 0 | AH32: NA | AI32: 0 | AJ32: 0 | AK32: 0 | AL32: NA | AM32: 0 | AN32: 0 | AO32: 0 | AP32: NA | AQ32: 0 | AR32: 0 | AS32: 0 | AT32: NA | AU32: 0 | AV32: 0 | AW32: 0 | AX32: NA | AY32: 0 | AZ32: 0 | BA32: 0 | BB32: IMPORTACIONES RUBI S.A. | BC32: 1000427925 | BD32: REGULAR_OMD_PR
A33: 32 | B33: Cooking | C33: PE000820001B | D33: MS4296DIR.BBKGLPR | E33: 20230228 | F33: 01-F001-00252838 | G33: 2023W08 | H33: PEN | I33: 27 | J33: 433.98 | K33: 11717.46 | L33: 3.816 | M33: 433.98 | N33: NA | O33: 0 | P33: 0 | Q33: 0 | R33: NA | S33: 0 | T33: 0 | U33: 0 | V33: NA | W33: 0 | X33: 0 | Y33: 0 | Z33: NA | AA33: 0 | AB33: 0 | AC33: 0 | AD33: NA | AE33: 0 | AF33: 0 | AG33: 0 | AH33: NA | AI33: 0 | AJ33: 0 | AK33: 0 | AL33: NA | AM33: 0 | AN33: 0 | AO33: 0 | AP33: NA | AQ33: 0 | AR33: 0 | AS33: 0 | AT33: NA | AU33: 0 | AV33: 0 | AW33: 0 | AX33: NA | AY33: 0 | AZ33: 0 | BA33: 0 | BB33: IMPORTACIONES RUBI S.A. | BC33: 1000424246 | BD33: REGULAR_OMD_PR
A34: 33 | B34: Cooking | C34: PE000820001B | D34: MS4296DIR.BBKGLPR | E34: 20230130 | F34: 01-F001-00251245 | G34: 2023W02 | H34: PEN | I34: 20 | J34: 433.98 | K34: 8679.6 | L34: 3.829 | M34: 433.98 | N34: NA | O34: 0 | P34: 0 | Q34: 0 | R34: NA | S34: 0 | T34: 0 | U34: 0 | V34: NA | W34: 0 | X34: 0 | Y34: 0 | Z34: NA | AA34: 0 | AB34: 0 | AC34: 0 | AD34: NA | AE34: 0 | AF34: 0 | AG34: 0 | AH34: NA | AI34: 0 | AJ34: 0 | AK34: 0 | AL34: NA | AM34: 0 | AN34: 0 | AO34: 0 | AP34: NA | AQ34: 0 | AR34: 0 | AS34: 0 | AT34: NA | AU34: 0 | AV34: 0 | AW34: 0 | AX34: NA | AY34: 0 | AZ34: 0 | BA34: 0 | BB34: IMPORTACIONES RUBI S.A. | BC34: 1000422908 | BD34: REGULAR_OMD_PR
A35: 34 | B35: Cooking | C35: PE000820001B | D35: MS4296DIR.BBKGLPR | E35: 20220930 | G35: 2022W39 | H35: PEN | I35: 10 | J35: 433.98 | K35: 4339.8 | L35: 3.971 | M35: 433.98 | N35: NA | O35: 0 | P35: 0 | Q35: 0 | R35: NA | S35: 0 | T35: 0 | U35: 0 | V35: NA | W35: 0 | X35: 0 | Y35: 0 | Z35: NA | AA35: 0 | AB35: 0 | AC35: 0 | AD35: NA | AE35: 0 | AF35: 0 | AG35: 0 | AH35: NA | AI35: 0 | AJ35: 0 | AK35: 0 | AL35: NA | AM35: 0 | AN35: 0 | AO35: 0 | AP35: NA | AQ35: 0 | AR35: 0 | AS35: 0 | AT35: NA | AU35: 0 | AV35: 0 | AW35: 0 | AX35: NA | AY35: 0 | AZ35: 0 | BA35: 0 | BB35: IMPORTACIONES RUBI S.A. | BC35: 1000419825 | BD35: REGULAR_OMD_PR
A36: 35 | B36: Cooking | C36: PE000820001B | D36: MS4296DIR.BBKGLPR | E36: 20220408 | G36: 2022W12 | H36: PEN | I36: 50 | J36: 426.36 | K36: 21318 | L36: 3.714 | M36: 426.36 | N36: NA | O36: 0 | P36: 0 | Q36: 0 | R36: NA | S36: 0 | T36: 0 | U36: 0 | V36: NA | W36: 0 | X36: 0 | Y36: 0 | Z36: NA | AA36: 0 | AB36: 0 | AC36: 0 | AD36: NA | AE36: 0 | AF36: 0 | AG36: 0 | AH36: NA | AI36: 0 | AJ36: 0 | AK36: 0 | AL36: NA | AM36: 0 | AN36: 0 | AO36: 0 | AP36: NA | AQ36: 0 | AR36: 0 | AS36: 0 | AT36: NA | AU36: 0 | AV36: 0 | AW36: 0 | AX36: NA | AY36: 0 | AZ36: 0 | BA36: 0 | BB36: IMPORTACIONES RUBI S.A. | BC36: 1000414682 | BD36: REGULAR_OMD_PR
A37: 36 | B37: Cooking | C37: PE000820001B | D37: MS4296DIR.BBKGLPR | E37: 20211217 | G37: 2021W50 | H37: PEN | I37: 14 | J37: 449.24 | K37: 6289.36 | L37: 4.04 | M37: 449.24 | N37: NA | O37: 0 | P37: 0 | Q37: 0 | R37: NA | S37: 0 | T37: 0 | U37: 0 | V37: NA | W37: 0 | X37: 0 | Y37: 0 | Z37: NA | AA37: 0 | AB37: 0 | AC37: 0 | AD37: NA | AE37: 0 | AF37: 0 | AG37: 0 | AH37: NA | AI37: 0 | AJ37: 0 | AK37: 0 | AL37: NA | AM37: 0 | AN37: 0 | AO37: 0 | AP37: NA | AQ37: 0 | AR37: 0 | AS37: 0 | AT37: NA | AU37: 0 | AV37: 0 | AW37: 0 | AX37: NA | AY37: 0 | AZ37: 0 | BA37: 0 | BB37: IMPORTACIONES RUBI S.A. | BC37: 1000411402 | BD37: REGULAR_OMD_PR
A38: 37 | B38: Cooking | C38: PE000820001B | D38: MS4296DIR.BBKGLPR | E38: 20211127 | F38: 01-F001-00230500 | G38: 2021W43 | H38: PEN | I38: 6 | J38: 456.86 | K38: 2741.16 | L38: 4.041 | M38: 456.86 | N38: NA | O38: 0 | P38: 0 | Q38: 0 | R38: NA | S38: 0 | T38: 0 | U38: 0 | V38: NA | W38: 0 | X38: 0 | Y38: 0 | Z38: NA | AA38: 0 | AB38: 0 | AC38: 0 | AD38: NA | AE38: 0 | AF38: 0 | AG38: 0 | AH38: NA | AI38: 0 | AJ38: 0 | AK38: 0 | AL38: NA | AM38: 0 | AN38: 0 | AO38: 0 | AP38: NA | AQ38: 0 | AR38: 0 | AS38: 0 | AT38: NA | AU38: 0 | AV38: 0 | AW38: 0 | AX38: NA | AY38: 0 | AZ38: 0 | BA38: 0 | BB38: IMPORTACIONES RUBI S.A. | BC38: 1000410134 | BD38: REGULAR_OMD_PR
A39: 38 | B39: Cooking | C39: PE000820001B | D39: MS4296DIR.BBKGLPR | E39: 20211126 | F39: 01-F001-00230210 | G39: 2021W44 | H39: PEN | I39: 8 | J39: 456.86 | K39: 3654.88 | L39: 4.031 | M39: 456.86 | N39: NA | O39: 0 | P39: 0 | Q39: 0 | R39: NA | S39: 0 | T39: 0 | U39: 0 | V39: NA | W39: 0 | X39: 0 | Y39: 0 | Z39: NA | AA39: 0 | AB39: 0 | AC39: 0 | AD39: NA | AE39: 0 | AF39: 0 | AG39: 0 | AH39: NA | AI39: 0 | AJ39: 0 | AK39: 0 | AL39: NA | AM39: 0 | AN39: 0 | AO39: 0 | AP39: NA | AQ39: 0 | AR39: 0 | AS39: 0 | AT39: NA | AU39: 0 | AV39: 0 | AW39: 0 | AX39: NA | AY39: 0 | AZ39: 0 | BA39: 0 | BB39: IMPORTACIONES RUBI S.A. | BC39: 1000410406 | BD39: REGULAR_OMD_PR
A40: 39 | B40: Cooking | C40: PE000820001B | D40: MS4296DIR.BBKGLPR | E40: 20211113 | F40: 01-F001-00229116 | G40: 2021W43 | H40: PEN | I40: 2 | J40: 456.86 | K40: 913.72 | L40: 4.026 | M40: 456.86 | N40: NA | O40: 0 | P40: 0 | Q40: 0 | R40: NA | S40: 0 | T40: 0 | U40: 0 | V40: NA | W40: 0 | X40: 0 | Y40: 0 | Z40: NA | AA40: 0 | AB40: 0 | AC40: 0 | AD40: NA | AE40: 0 | AF40: 0 | AG40: 0 | AH40: NA | AI40: 0 | AJ40: 0 | AK40: 0 | AL40: NA | AM40: 0 | AN40: 0 | AO40: 0 | AP40: NA | AQ40: 0 | AR40: 0 | AS40: 0 | AT40: NA | AU40: 0 | AV40: 0 | AW40: 0 | AX40: NA | AY40: 0 | AZ40: 0 | BA40: 0 | BB40: IMPORTACIONES RUBI S.A. | BC40: 1000410134 | BD40: REGULAR_OMD_PR
...

Sheet MIX_DETAIL
A1: CUSTOMER | B1: MODEL | C1: LINE SEQ | D1: LIQ START DATE | E1: LIQ END DATE | F1: LIQ QTY | G1: LIQ COST | H1: LIQ NEW COST | I1: DIFF | J1: REF LINE SEQ | K1: REF START DATE | L1: REF END DATE | M1: REF LIQ QTY | N1: REF COST | O1: REF NEW COST | P1: REF DIFF | Q1: ADJ START DATE | R1: ADJ END DATE | S1: ADJ LIQ QTY | T1: CUSTOMER QTY | U1: ADJ COST | V1: ADJ NEW COST | W1: ADJ DIFF | X1: ADJ AMOUNT
D2: 45411.701 | E2: 45411.701 | F2: 0 | G2: 0 | H2: 0 | I2: 0 | K2: 45411.701 | L2: 45411.701 | M2: 0 | N2: 0 | O2: 0 | P2: 0 | Q2: 45411.701 | R2: 45411.701 | S2: 0 | T2: 0 | U2: 0 | V2: 0 | W2: 0 | X2: 0

Sheet SPMS
A1: Promotion No | B1: Promotion Name | C1: Promotion Status Code | D1: Approved Date | E1: Promotion Start YYYYMMDD | F1: Promotion End YYYYMMDD | G1: Requestor Name | H1: Transaction Currency Code | I1: Promotion Property | J1: Subsidiary Dff1 | K1: Subsidiary Dff2 | L1: Subsidiary Dff3 | M1: Subsidiary Dff4 | N1: Subsidiary Dff5 | O1: Subsidiary Dff6 | P1: Line No | Q1: Budget Check Signal | R1: Promotion Line Status Code | S1: Sales PGM Reason Code | T1: Sales PGM Reason Name | U1: Sales PGM Type | V1: Customer Type | W1: Customer Code | X1: Customer Name | Y1: Product Type | Z1: Product Code | AA1: Division Code | AB1: Division Name | AC1: Calculation Method | AD1: Dc Operand | AE1: Expected Qty | AF1: Expected Cost | AG1: Sales PGM Status | AH1: Sales PGM Name | AI1: Sales PGM NO | AJ1: Sales PGM Product Code | AK1: Sales PGM Product Type | AL1: Offer Dc Operand | AM1: Offer Expected Qty | AN1: Offer Expected Cost | AO1: Sales PGM Approved YYYYMM | AP1: Sales PGM Approved YYYYMMDD | AQ1: Line Remark | AR1: Promotion Price | AS1: New Margin | AT1: Bundle Model Code | AU1: Limit Qty | AV1: Bundle Cost Rate | AW1: Cancel Flag
A2: PR-NTSO-20240327-0059 | B2: 2024 - RUBI - W/M - 20240403 AL 20240430 | C2: APPROVED | D2: 45378.761 | E2: 20240403 | F2: 20240430 | G2: Castillo Jose | H2: PEN | I2: NTTSO | K2: ALL | P2: 1 | Q2: G | R2: APPROVED | S2: TM_Z02 | T2: Sell out Support Rebate | U2: LUMPSUM | V2: Bill To | W2: PE000820001B | X2: IMPORTACIONES RUBI S.A. | Y2: Model | Z2: WD12BVC2S6C.ABLGLGP | AA2: DFT | AB2: W/M | AC2: AMT | AD2: 678.82 | AE2: 10 | AF2: 6788.2 | AJ2: WD12BVC2S6C.ABLGLGP | AK2: Model | AL2: 0 | AM2: 0 | AN2: 0 | AQ2: 2099_10__ | AR2: 2099 | AS2: 10 | AU2: 0 | AV2: N | AW2: N
A3: PR-NTSO-20240327-0059 | B3: 2024 - RUBI - W/M - 20240403 AL 20240430 | C3: APPROVED | D3: 45378.761 | E3: 20240403 | F3: 20240430 | G3: Castillo Jose | H3: PEN | I3: NTTSO | K3: ALL | P3: 2 | Q3: G | R3: APPROVED | S3: TM_Z02 | T3: Sell out Support Rebate | U3: LUMPSUM | V3: Bill To | W3: PE000820001B | X3: IMPORTACIONES RUBI S.A. | Y3: Model | Z3: WD14BVC2S6C.ABLGLGP | AA3: DFT | AB3: W/M | AC3: AMT | AD3: 152.54 | AE3: 14 | AF3: 2135.56 | AJ3: WD14BVC2S6C.ABLGLGP | AK3: Model | AL3: 0 | AM3: 0 | AN3: 0 | AQ3: 2799_10__ | AR3: 2799 | AS3: 10 | AU3: 0 | AV3: N | AW3: N
A4: PR-NTSO-20240327-0059 | B4: 2024 - RUBI - W/M - 20240403 AL 20240430 | C4: APPROVED | D4: 45378.761 | E4: 20240403 | F4: 20240430 | G4: Castillo Jose | H4: PEN | I4: NTTSO | K4: ALL | P4: 3 | Q4: G | R4: APPROVED | S4: TM_Z02 | T4: Sell out Support Rebate | U4: LUMPSUM | V4: Bill To | W4: PE000820001B | X4: IMPORTACIONES RUBI S.A. | Y4: Model | Z4: WD15EG2S.AESGLGP | AA4: DFT | AB4: W/M | AC4: AMT | AD4: 1144.07 | AE4: 7 | AF4: 8008.49 | AJ4: WD15EG2S.AESGLGP | AK4: Model | AL4: 0 | AM4: 0 | AN4: 0 | AQ4: 2949_10__ | AR4: 2949 | AS4: 10 | AU4: 0 | AV4: N | AW4: N
A5: PR-NTSO-20240327-0059 | B5: 2024 - RUBI - W/M - 20240403 AL 20240430 | C5: APPROVED | D5: 45378.761 | E5: 20240403 | F5: 20240430 | G5: Castillo Jose | H5: PEN | I5: NTTSO | K5: ALL | P5: 4 | Q5: G | R5: APPROVED | S5: TM_Z02 | T5: Sell out Support Rebate | U5: LUMPSUM | V5: Bill To | W5: PE000820001B | X5: IMPORTACIONES RUBI S.A. | Y5: Model | Z5: WT19BPB.ABMGLGP | AA5: DFT | AB5: W/M | AC5: AMT | AD5: 245.81 | AE5: 30 | AF5: 7374.3 | AJ5: WT19BPB.ABMGLGP | AK5: Model | AL5: 0 | AM5: 0 | AN5: 0 | AQ5: 1399_5__ | AR5: 1399 | AS5: 5 | AU5: 0 | AV5: N | AW5: N
A6: PR-NTSO-20240405-0031 | B6: 2024 - RUBI - Cooking - 20240410 AL 20240430 | C6: APPROVED | D6: 45387.632 | E6: 20240410 | F6: 20240430 | G6: Castillo Jose | H6: PEN | I6: NTTSO | K6: ALL | P6: 1 | Q6: G | R6: APPROVED | S6: TM_Z02 | T6: Sell out Support Rebate | U6: LUMPSUM | V6: Bill To | W6: PE000820001B | X6: IMPORTACIONES RUBI S.A. | Y6: Model | Z6: RSG314M.FSTGLPR | AA6: CVT | AB6: Cooking | AC6: AMT | AD6: 724.57 | AE6: 8 | AF6: 5796.56 | AJ6: RSG314M.FSTGLPR | AK6: Model | AL6: 0 | AM6: 0 | AN6: 0 | AQ6: 1599_10__8 | AR6: 1599 | AS6: 10 | AU6: 8 | AV6: N | AW6: N
A7: PR-NTSO-20240415-0011 | B7: 2024 - RUBI - Cooking - 20240420 AL 20240430 | C7: APPROVED | D7: 45398.44 | E7: 20240420 | F7: 20240430 | G7: Castillo Jose | H7: PEN | I7: NTTSO | K7: ALL | P7: 1 | Q7: G | R7: APPROVED | S7: TM_Z02 | T7: Sell out Support Rebate | U7: LUMPSUM | V7: Bill To | W7: PE000820001B | X7: IMPORTACIONES RUBI S.A. | Y7: Model | Z7: MS2596DIR.BBKGLPR | AA7: CVT | AB7: Cooking | AC7: AMT | AD7: 76.27 | AE7: 21 | AF7: 1601.67 | AJ7: MS2596DIR.BBKGLPR | AK7: Model | AL7: 0 | AM7: 0 | AN7: 0 | AQ7: 379_10__ | AR7: 379 | AS7: 10 | AU7: 0 | AV7: N | AW7: N
A8: PR-NTSO-20240416-0005 | B8: 2024 - RUBI - Cooking - 20240422 AL 20240430 | C8: APPROVED | D8: 45398.833 | E8: 20240422 | F8: 20240430 | G8: Castillo Jose | H8: PEN | I8: NTTSO | K8: ALL | P8: 1 | Q8: G | R8: APPROVED | S8: TM_Z02 | T8: Sell out Support Rebate | U8: LUMPSUM | V8: Bill To | W8: PE000820001B | X8: IMPORTACIONES RUBI S.A. | Y8: Model | Z8: MS4296DIR.BBKGLPR | AA8: CVT | AB8: Cooking | AC8: AMT | AD8: 7.63 | AE8: 140 | AF8: 1068.2 | AJ8: MS4296DIR.BBKGLPR | AK8: Model | AL8: 0 | AM8: 0 | AN8: 0 | AQ8: 539_10__ | AR8: 539 | AS8: 10 | AU8: 0 | AV8: N | AW8: N
A9: PR-NTSO-20240416-0005 | B9: 2024 - RUBI - Cooking - 20240422 AL 20240430 | C9: APPROVED | D9: 45398.833 | E9: 20240422 | F9: 20240430 | G9: Castillo Jose | H9: PEN | I9: NTTSO | K9: ALL | P9: 2 | Q9: G | R9: APPROVED | S9: TM_Z02 | T9: Sell out Support Rebate | U9: LUMPSUM | V9: Bill To | W9: PE000820001B | X9: IMPORTACIONES RUBI S.A. | Y9: Model | Z9: RSG314M.FSTGLPR | AA9: CVT | AB9: Cooking | AC9: AMT | AD9: 724.57 | AE9: 10 | AF9: 7245.7 | AJ9: RSG314M.FSTGLPR | AK9: Model | AL9: 0 | AM9: 0 | AN9: 0 | AQ9: 1599_10__ | AR9: 1599 | AS9: 10 | AU9: 0 | AV9: N | AW9: N
